Workbook

Sheet START HERE
B2: DEBT PAYOFF PLANNER
B4: Snowball or Avalanche — see your projected debt-free date either way.
B6: HOW TO USE
B7: 1. 'My Debts' tab: list every debt in the yellow cells (up to 10) and your extra payment at the top.
B8: 2. The Snowball and Avalanche tabs re-order your debts automatically and run the month-by-month
B9: math: your projected debt-free month and year, per debt and overall, plus total interest.
B10: 3. 'The Verdict' on My Debts puts both plans side by side. Pick the one you'll actually stick to.
B11: 4. Log every win on the Progress tab — the charts there update as you pay things down.
B13: COLOR LEGEND
B14: Yellow cells = yours to edit. Everything else calculates automatically — please don't type over it.
B15: The strategy tabs and the two Schedule tabs have NO yellow: they are 100% calculated for you.
B16: The pre-filled numbers are a realistic example — replace them with your own.
... B33: Questions? Message us — real humans, fast replies, we'll fix anything.

Sheet My Debts
B2: MY DEBTS
B4: Monthly EXTRA payment (beyond minimums): | E4: 150
B6: Debt name | C6: Balance | D6: APR | E6: Min payment | F6: Notes
B7: Store card | C7: 640 | D7: 0.279 | E7: 35
B8: Medical bill | C8: 1200 | D8: 0 | E8: 50
B9: Credit card A | C9: 2850 | D9: 0.246 | E9: 75
B10: Credit card B | C10: 4100 | D10: 0.219 | E10: 95
B11: Car loan | C11: 9400 | D11: 0.069 | E11: 310
B17: Total | C17: =SUM(C7:C16) -> 18190 | E17: =SUM(E7:E16) -> 565
B19: Total monthly attack (minimums + extra): | E19: =E17+E4 -> 715
B21: THE VERDICT — PICK YOUR PLAN
B22: Strategy | C22: Debt-free date | D22: Months | E22: Total interest
B23: Snowball | C23: =IF('Snowball Schedule'!$L$14<=0,"—",IF('Snowball Schedule'!$O$2=999,"30+ years",TEXT(EDATE(TODAY(),'Snowball Schedule'!$O$2),"MMM YYYY"))) -> Mar 2029 | D23: =IF('Snowball Schedule'!$L$14<=0,"—",IF('Snowball Schedule'!$O$2=999,"360+",'Snowball Schedule'!$O$2)) -> 31 | E23: =IF('Snowball Schedule'!$L$14<=0,"—",ROUND('Snowball Schedule'!$O$3,2)) -> 3387.3
B24: Avalanche | C24: =IF('Avalanche Schedule'!$L$14<=0,"—",IF('Avalanche Schedule'!$O$2=999,"30+ years",TEXT(EDATE(TODAY(),'Avalanche Schedule'!$O$2),"MMM YYYY"))) -> Feb 2029 | D24: =IF('Avalanche Schedule'!$L$14<=0,"—",IF('Avalanche Schedule'!$O$2=999,"360+",'Avalanche Schedule'!$O$2)) -> 30 | E24: =IF('Avalanche Schedule'!$L$14<=0,"—",ROUND('Avalanche Schedule'!$O$3,2)) -> 3163.88
B25: Same monthly attack either way. Snowball = faster first wins; Avalanche usually pays less interest. The Schedule tabs show every month of the math.

Sheet Snowball
B2: SNOWBALL PLAN
B4: Smallest balance first for quick wins. This tab reads My Debts, re-orders itself, and runs the month-by-month math — nothing to type here.
B6: PROJECTED DEBT-FREE DATE | D6: =IF('Snowball Schedule'!$L$14<=0,"add your debts first",IF('Snowball Schedule'!$O$2=999,"30+ years — raise your payment",TEXT(EDATE(TODAY(),'Snowball Schedule'!$O$2),"MMMM YYYY"))) -> March 2029
B7: Months from today | D7: =IF('Snowball Schedule'!$L$14<=0,"—",IF('Snowball Schedule'!$O$2=999,"360+",'Snowball Schedule'!$O$2)) -> 31
B8: Total interest on this plan | D8: =IF('Snowball Schedule'!$L$14<=0,"—",ROUND('Snowball Schedule'!$O$3,2)) -> 3387.3
B9: Months saved by your extra payment | D9: =IF('Snowball Schedule'!$L$14<=0,"—",IF(OR('Snowball Schedule'!$O$2=999,'Snowball Schedule'!$O$4=999),"—",'Snowball Schedule'!$O$4-'Snowball Schedule'!$O$2)) -> 11
B10: Interest saved by your extra payment | D10: =IF('Snowball Schedule'!$L$14<=0,"—",IF(OR('Snowball Schedule'!$O$2=999,'Snowball Schedule'!$O$4=999),"—",ROUND('Snowball Schedule'!$O$5-'Snowball Schedule'!$O$3,2))) -> 2072.27
B12: Debt (attack order) | C12: Balance | D12: APR | E12: Min payment | F12: Paid off (month #) | G12: Debt-free date
B13: =INDEX('Snowball Schedule'!$B$6:$K$6,1) -> Store card | C13: =IF(INDEX('Snowball Schedule'!$B$5:$K$5,1)<=0,"",INDEX('Snowball Schedule'!$B$5:$K$5,1)) -> 640 | D13: =IF(C13="","",INDEX('Snowball Schedule'!$B$7:$K$7,1)) -> 0.279 | E13: =IF(C13="","",INDEX('Snowball Schedule'!$B$9:$K$9,1)) -> 35 | F13: =IF(C13="","",IF(INDEX('Snowball Schedule'!$B$10:$K$10,1)=999,"360+",INDEX('Snowball Schedule'!$B$10:$K$10,1))) -> 4 | G13: =IF(C13="","",IF(INDEX('Snowball Schedule'!$B$10:$K$10,1)=999,"—",TEXT(EDATE(TODAY(),INDEX('Snowball Schedule'!$B$10:$K$10,1)),"MMM YYYY"))) -> Dec 2026
B14: =INDEX('Snowball Schedule'!$B$6:$K$6,2) -> Medical bill | C14: =IF(INDEX('Snowball Schedule'!$B$5:$K$5,2)<=0,"",INDEX('Snowball Schedule'!$B$5:$K$5,2)) -> 1200 | D14: =IF(C14="","",INDEX('Snowball Schedule'!$B$7:$K$7,2)) -> 0 | E14: =IF(C14="","",INDEX('Snowball Schedule'!$B$9:$K$9,2)) -> 50 | F14: =IF(C14="","",IF(INDEX('Snowball Schedule'!$B$10:$K$10,2)=999,"360+",INDEX('Snowball Schedule'!$B$10:$K$10,2))) -> 8 | G14: =IF(C14="","",IF(INDEX('Snowball Schedule'!$B$10:$K$10,2)=999,"—",TEXT(EDATE(TODAY(),INDEX('Snowball Schedule'!$B$10:$K$10,2)),"MMM YYYY"))) -> Apr 2027
B15: =INDEX('Snowball Schedule'!$B$6:$K$6,3) -> Credit card A | C15: =IF(INDEX('Snowball Schedule'!$B$5:$K$5,3)<=0,"",INDEX('Snowball Schedule'!$B$5:$K$5,3)) -> 2850 | D15: =IF(C15="","",INDEX('Snowball Schedule'!$B$7:$K$7,3)) -> 0.246 | E15: =IF(C15="","",INDEX('Snowball Schedule'!$B$9:$K$9,3)) -> 75 | F15: =IF(C15="","",IF(INDEX('Snowball Schedule'!$B$10:$K$10,3)=999,"360+",INDEX('Snowball Schedule'!$B$10:$K$10,3))) -> 18 | G15: =IF(C15="","",IF(INDEX('Snowball Schedule'!$B$10:$K$10,3)=999,"—",TEXT(EDATE(TODAY(),INDEX('Snowball Schedule'!$B$10:$K$10,3)),"MMM YYYY"))) -> Feb 2028
B16: =INDEX('Snowball Schedule'!$B$6:$K$6,4) -> Credit card B | C16: =IF(INDEX('Snowball Schedule'!$B$5:$K$5,4)<=0,"",INDEX('Snowball Schedule'!$B$5:$K$5,4)) -> 4100 | D16: =IF(C16="","",INDEX('Snowball Schedule'!$B$7:$K$7,4)) -> 0.219 | E16: =IF(C16="","",INDEX('Snowball Schedule'!$B$9:$K$9,4)) -> 95 | F16: =IF(C16="","",IF(INDEX('Snowball Schedule'!$B$10:$K$10,4)=999,"360+",INDEX('Snowball Schedule'!$B$10:$K$10,4))) -> 28 | G16: =IF(C16="","",IF(INDEX('Snowball Schedule'!$B$10:$K$10,4)=999,"—",TEXT(EDATE(TODAY(),INDEX('Snowball Schedule'!$B$10:$K$10,4)),"MMM YYYY"))) -> Dec 2028
B17: =INDEX('Snowball Schedule'!$B$6:$K$6,5) -> Car loan | C17: =IF(INDEX('Snowball Schedule'!$B$5:$K$5,5)<=0,"",INDEX('Snowball Schedule'!$B$5:$K$5,5)) -> 9400 | D17: =IF(C17="","",INDEX('Snowball Schedule'!$B$7:$K$7,5)) -> 0.069 | E17: =IF(C17="","",INDEX('Snowball Schedule'!$B$9:$K$9,5)) -> 310 | F17: =IF(C17="","",IF(INDEX('Snowball Schedule'!$B$10:$K$10,5)=999,"360+",INDEX('Snowball Schedule'!$B$10:$K$10,5))) -> 31 | G17: =IF(C17="","",IF(INDEX('Snowball Schedule'!$B$10:$K$10,5)=999,"—",TEXT(EDATE(TODAY(),INDEX('Snowball Schedule'!$B$10:$K$10,5)),"MMM YYYY"))) -> Mar 2029
B18: =INDEX('Snowball Schedule'!$B$6:$K$6,6) | C18: =IF(INDEX('Snowball Schedule'!$B$5:$K$5,6)<=0,"",INDEX('Snowball Schedule'!$B$5:$K$5,6)) | D18: =IF(C18="","",INDEX('Snowball Schedule'!$B$7:$K$7,6)) | E18: =IF(C18="","",INDEX('Snowball Schedule'!$B$9:$K$9,6)) | F18: =IF(C18="","",IF(INDEX('Snowball Schedule'!$B$10:$K$10,6)=999,"360+",INDEX('Snowball Schedule'!$B$10:$K$10,6))) | G18: =IF(C18="","",IF(INDEX('Snowball Schedule'!$B$10:$K$10,6)=999,"—",TEXT(EDATE(TODAY(),INDEX('Snowball Schedule'!$B$10:$K$10,6)),"MMM YYYY")))
B19: =INDEX('Snowball Schedule'!$B$6:$K$6,7) | C19: =IF(INDEX('Snowball Schedule'!$B$5:$K$5,7)<=0,"",INDEX('Snowball Schedule'!$B$5:$K$5,7)) | D19: =IF(C19="","",INDEX('Snowball Schedule'!$B$7:$K$7,7)) | E19: =IF(C19="","",INDEX('Snowball Schedule'!$B$9:$K$9,7)) | F19: =IF(C19="","",IF(INDEX('Snowball Schedule'!$B$10:$K$10,7)=999,"360+",INDEX('Snowball Schedule'!$B$10:$K$10,7))) | G19: =IF(C19="","",IF(INDEX('Snowball Schedule'!$B$10:$K$10,7)=999,"—",TEXT(EDATE(TODAY(),INDEX('Snowball Schedule'!$B$10:$K$10,7)),"MMM YYYY")))
B20: =INDEX('Snowball Schedule'!$B$6:$K$6,8) | C20: =IF(INDEX('Snowball Schedule'!$B$5:$K$5,8)<=0,"",INDEX('Snowball Schedule'!$B$5:$K$5,8)) | D20: =IF(C20="","",INDEX('Snowball Schedule'!$B$7:$K$7,8)) | E20: =IF(C20="","",INDEX('Snowball Schedule'!$B$9:$K$9,8)) | F20: =IF(C20="","",IF(INDEX('Snowball Schedule'!$B$10:$K$10,8)=999,"360+",INDEX('Snowball Schedule'!$B$10:$K$10,8))) | G20: =IF(C20="","",IF(INDEX('Snowball Schedule'!$B$10:$K$10,8)=999,"—",TEXT(EDATE(TODAY(),INDEX('Snowball Schedule'!$B$10:$K$10,8)),"MMM YYYY")))
B21: =INDEX('Snowball Schedule'!$B$6:$K$6,9) | C21: =IF(INDEX('Snowball Schedule'!$B$5:$K$5,9)<=0,"",INDEX('Snowball Schedule'!$B$5:$K$5,9)) | D21: =IF(C21="","",INDEX('Snowball Schedule'!$B$7:$K$7,9)) | E21: =IF(C21="","",INDEX('Snowball Schedule'!$B$9:$K$9,9)) | F21: =IF(C21="","",IF(INDEX('Snowball Schedule'!$B$10:$K$10,9)=999,"360+",INDEX('Snowball Schedule'!$B$10:$K$10,9))) | G21: =IF(C21="","",IF(INDEX('Snowball Schedule'!$B$10:$K$10,9)=999,"—",TEXT(EDATE(TODAY(),INDEX('Snowball Schedule'!$B$10:$K$10,9)),"MMM YYYY")))
B22: =INDEX('Snowball Schedule'!$B$6:$K$6,10) | C22: =IF(INDEX('Snowball Schedule'!$B$5:$K$5,10)<=0,"",INDEX('Snowball Schedule'!$B$5:$K$5,10)) | D22: =IF(C22="","",INDEX('Snowball Schedule'!$B$7:$K$7,10)) | E22: =IF(C22="","",INDEX('Snowball Schedule'!$B$9:$K$9,10)) | F22: =IF(C22="","",IF(INDEX('Snowball Schedule'!$B$10:$K$10,10)=999,"360+",INDEX('Snowball Schedule'!$B$10:$K$10,10))) | G22: =IF(C22="","",IF(INDEX('Snowball Schedule'!$B$10:$K$10,10)=999,"—",TEXT(EDATE(TODAY(),INDEX('Snowball Schedule'!$B$10:$K$10,10)),"MMM YYYY")))
B24: How the math works: interest compounds monthly (APR ÷ 12); every debt gets its minimum; your whole extra payment plus every freed-up minimum attacks the top unpaid debt.
B25: Dates project from today. Nothing on this tab is typed by you — it all follows My Debts. Full month-by-month math: see the Snowball Schedule tab.

Sheet Avalanche
B2: AVALANCHE PLAN
B4: Highest interest rate first — the mathematically cheapest path. Reads My Debts and re-orders itself; nothing to type here.
B6: PROJECTED DEBT-FREE DATE | D6: =IF('Avalanche Schedule'!$L$14<=0,"add your debts first",IF('Avalanche Schedule'!$O$2=999,"30+ years — raise your payment",TEXT(EDATE(TODAY(),'Avalanche Schedule'!$O$2),"MMMM YYYY"))) -> February 2029
B7: Months from today | D7: =IF('Avalanche Schedule'!$L$14<=0,"—",IF('Avalanche Schedule'!$O$2=999,"360+",'Avalanche Schedule'!$O$2)) -> 30
B8: Total interest on this plan | D8: =IF('Avalanche Schedule'!$L$14<=0,"—",ROUND('Avalanche Schedule'!$O$3,2)) -> 3163.88
B9: Months saved by your extra payment | D9: =IF('Avalanche Schedule'!$L$14<=0,"—",IF(OR('Avalanche Schedule'!$O$2=999,'Avalanche Schedule'!$O$4=999),"—",'Avalanche Schedule'!$O$4-'Avalanche Schedule'!$O$2)) -> 12
B10: Interest saved by your extra payment | D10: =IF('Avalanche Schedule'!$L$14<=0,"—",IF(OR('Avalanche Schedule'!$O$2=999,'Avalanche Schedule'!$O$4=999),"—",ROUND('Avalanche Schedule'!$O$5-'Avalanche Schedule'!$O$3,2))) -> 2295.69
B12: Debt (attack order) | C12: Balance | D12: APR | E12: Min payment | F12: Paid off (month #) | G12: Debt-free date
B13: =INDEX('Avalanche Schedule'!$B$6:$K$6,1) -> Store card | C13: =IF(INDEX('Avalanche Schedule'!$B$5:$K$5,1)<=0,"",INDEX('Avalanche Schedule'!$B$5:$K$5,1)) -> 640 | D13: =IF(C13="","",INDEX('Avalanche Schedule'!$B$7:$K$7,1)) -> 0.279 | E13: =IF(C13="","",INDEX('Avalanche Schedule'!$B$9:$K$9,1)) -> 35 | F13: =IF(C13="","",IF(INDEX('Avalanche Schedule'!$B$10:$K$10,1)=999,"360+",INDEX('Avalanche Schedule'!$B$10:$K$10,1))) -> 4 | G13: =IF(C13="","",IF(INDEX('Avalanche Schedule'!$B$10:$K$10,1)=999,"—",TEXT(EDATE(TODAY(),INDEX('Avalanche Schedule'!$B$10:$K$10,1)),"MMM YYYY"))) -> Dec 2026
B14: =INDEX('Avalanche Schedule'!$B$6:$K$6,2) -> Credit card A | C14: =IF(INDEX('Avalanche Schedule'!$B$5:$K$5,2)<=0,"",INDEX('Avalanche Schedule'!$B$5:$K$5,2)) -> 2850 | D14: =IF(C14="","",INDEX('Avalanche Schedule'!$B$7:$K$7,2)) -> 0.246 | E14: =IF(C14="","",INDEX('Avalanche Schedule'!$B$9:$K$9,2)) -> 75 | F14: =IF(C14="","",IF(INDEX('Avalanche Schedule'!$B$10:$K$10,2)=999,"360+",INDEX('Avalanche Schedule'!$B$10:$K$10,2))) -> 16 | G14: =IF(C14="","",IF(INDEX('Avalanche Schedule'!$B$10:$K$10,2)=999,"—",TEXT(EDATE(TODAY(),INDEX('Avalanche Schedule'!$B$10:$K$10,2)),"MMM YYYY"))) -> Dec 2027
B15: =INDEX('Avalanche Schedule'!$B$6:$K$6,3) -> Credit card B | C15: =IF(INDEX('Avalanche Schedule'!$B$5:$K$5,3)<=0,"",INDEX('Avalanche Schedule'!$B$5:$K$5,3)) -> 4100 | D15: =IF(C15="","",INDEX('Avalanche Schedule'!$B$7:$K$7,3)) -> 0.219 | E15: =IF(C15="","",INDEX('Avalanche Schedule'!$B$9:$K$9,3)) -> 95 | F15: =IF(C15="","",IF(INDEX('Avalanche Schedule'!$B$10:$K$10,3)=999,"360+",INDEX('Avalanche Schedule'!$B$10:$K$10,3))) -> 28 | G15: =IF(C15="","",IF(INDEX('Avalanche Schedule'!$B$10:$K$10,3)=999,"—",TEXT(EDATE(TODAY(),INDEX('Avalanche Schedule'!$B$10:$K$10,3)),"MMM YYYY"))) -> Dec 2028
B16: =INDEX('Avalanche Schedule'!$B$6:$K$6,4) -> Car loan | C16: =IF(INDEX('Avalanche Schedule'!$B$5:$K$5,4)<=0,"",INDEX('Avalanche Schedule'!$B$5:$K$5,4)) -> 9400 | D16: =IF(C16="","",INDEX('Avalanche Schedule'!$B$7:$K$7,4)) -> 0.069 | E16: =IF(C16="","",INDEX('Avalanche Schedule'!$B$9:$K$9,4)) -> 310 | F16: =IF(C16="","",IF(INDEX('Avalanche Schedule'!$B$10:$K$10,4)=999,"360+",INDEX('Avalanche Schedule'!$B$10:$K$10,4))) -> 30 | G16: =IF(C16="","",IF(INDEX('Avalanche Schedule'!$B$10:$K$10,4)=999,"—",TEXT(EDATE(TODAY(),INDEX('Avalanche Schedule'!$B$10:$K$10,4)),"MMM YYYY"))) -> Feb 2029
B17: =INDEX('Avalanche Schedule'!$B$6:$K$6,5) -> Medical bill | C17: =IF(INDEX('Avalanche Schedule'!$B$5:$K$5,5)<=0,"",INDEX('Avalanche Schedule'!$B$5:$K$5,5)) -> 1200 | D17: =IF(C17="","",INDEX('Avalanche Schedule'!$B$7:$K$7,5)) -> 0 | E17: =IF(C17="","",INDEX('Avalanche Schedule'!$B$9:$K$9,5)) -> 50 | F17: =IF(C17="","",IF(INDEX('Avalanche Schedule'!$B$10:$K$10,5)=999,"360+",INDEX('Avalanche Schedule'!$B$10:$K$10,5))) -> 24 | G17: =IF(C17="","",IF(INDEX('Avalanche Schedule'!$B$10:$K$10,5)=999,"—",TEXT(EDATE(TODAY(),INDEX('Avalanche Schedule'!$B$10:$K$10,5)),"MMM YYYY"))) -> Aug 2028
B18: =INDEX('Avalanche Schedule'!$B$6:$K$6,6) | C18: =IF(INDEX('Avalanche Schedule'!$B$5:$K$5,6)<=0,"",INDEX('Avalanche Schedule'!$B$5:$K$5,6)) | D18: =IF(C18="","",INDEX('Avalanche Schedule'!$B$7:$K$7,6)) | E18: =IF(C18="","",INDEX('Avalanche Schedule'!$B$9:$K$9,6)) | F18: =IF(C18="","",IF(INDEX('Avalanche Schedule'!$B$10:$K$10,6)=999,"360+",INDEX('Avalanche Schedule'!$B$10:$K$10,6))) | G18: =IF(C18="","",IF(INDEX('Avalanche Schedule'!$B$10:$K$10,6)=999,"—",TEXT(EDATE(TODAY(),INDEX('Avalanche Schedule'!$B$10:$K$10,6)),"MMM YYYY")))
B19: =INDEX('Avalanche Schedule'!$B$6:$K$6,7) | C19: =IF(INDEX('Avalanche Schedule'!$B$5:$K$5,7)<=0,"",INDEX('Avalanche Schedule'!$B$5:$K$5,7)) | D19: =IF(C19="","",INDEX('Avalanche Schedule'!$B$7:$K$7,7)) | E19: =IF(C19="","",INDEX('Avalanche Schedule'!$B$9:$K$9,7)) | F19: =IF(C19="","",IF(INDEX('Avalanche Schedule'!$B$10:$K$10,7)=999,"360+",INDEX('Avalanche Schedule'!$B$10:$K$10,7))) | G19: =IF(C19="","",IF(INDEX('Avalanche Schedule'!$B$10:$K$10,7)=999,"—",TEXT(EDATE(TODAY(),INDEX('Avalanche Schedule'!$B$10:$K$10,7)),"MMM YYYY")))
B20: =INDEX('Avalanche Schedule'!$B$6:$K$6,8) | C20: =IF(INDEX('Avalanche Schedule'!$B$5:$K$5,8)<=0,"",INDEX('Avalanche Schedule'!$B$5:$K$5,8)) | D20: =IF(C20="","",INDEX('Avalanche Schedule'!$B$7:$K$7,8)) | E20: =IF(C20="","",INDEX('Avalanche Schedule'!$B$9:$K$9,8)) | F20: =IF(C20="","",IF(INDEX('Avalanche Schedule'!$B$10:$K$10,8)=999,"360+",INDEX('Avalanche Schedule'!$B$10:$K$10,8))) | G20: =IF(C20="","",IF(INDEX('Avalanche Schedule'!$B$10:$K$10,8)=999,"—",TEXT(EDATE(TODAY(),INDEX('Avalanche Schedule'!$B$10:$K$10,8)),"MMM YYYY")))
B21: =INDEX('Avalanche Schedule'!$B$6:$K$6,9) | C21: =IF(INDEX('Avalanche Schedule'!$B$5:$K$5,9)<=0,"",INDEX('Avalanche Schedule'!$B$5:$K$5,9)) | D21: =IF(C21="","",INDEX('Avalanche Schedule'!$B$7:$K$7,9)) | E21: =IF(C21="","",INDEX('Avalanche Schedule'!$B$9:$K$9,9)) | F21: =IF(C21="","",IF(INDEX('Avalanche Schedule'!$B$10:$K$10,9)=999,"360+",INDEX('Avalanche Schedule'!$B$10:$K$10,9))) | G21: =IF(C21="","",IF(INDEX('Avalanche Schedule'!$B$10:$K$10,9)=999,"—",TEXT(EDATE(TODAY(),INDEX('Avalanche Schedule'!$B$10:$K$10,9)),"MMM YYYY")))
B22: =INDEX('Avalanche Schedule'!$B$6:$K$6,10) | C22: =IF(INDEX('Avalanche Schedule'!$B$5:$K$5,10)<=0,"",INDEX('Avalanche Schedule'!$B$5:$K$5,10)) | D22: =IF(C22="","",INDEX('Avalanche Schedule'!$B$7:$K$7,10)) | E22: =IF(C22="","",INDEX('Avalanche Schedule'!$B$9:$K$9,10)) | F22: =IF(C22="","",IF(INDEX('Avalanche Schedule'!$B$10:$K$10,10)=999,"360+",INDEX('Avalanche Schedule'!$B$10:$K$10,10))) | G22: =IF(C22="","",IF(INDEX('Avalanche Schedule'!$B$10:$K$10,10)=999,"—",TEXT(EDATE(TODAY(),INDEX('Avalanche Schedule'!$B$10:$K$10,10)),"MMM YYYY")))
B24: How the math works: interest compounds monthly (APR ÷ 12); every debt gets its minimum; your whole extra payment plus every freed-up minimum attacks the top unpaid debt.
B25: Dates project from today. Nothing on this tab is typed by you — it all follows My Debts. Full month-by-month math: see the Avalanche Schedule tab.

Sheet Progress
B2: PROGRESS — DEBTS DESTROYED
B4: Debt | C4: Paid off (date) | D4: Amount killed | E4: How it felt
B16: Total destroyed | D16: =SUM(D5:D14) -> 0
B18: Charts update from My Debts and the Schedule engines — nothing to type.

Sheet Snowball Schedule
A1: SNOWBALL ENGINE — month-by-month payoff math. Nothing to edit here; it recalculates from My Debts. Column banks: balances, then min-due and payment helpers, then the same engine run again with minimums only (for the 'saved' lines).
A2: Slot (attack order) | B2: 1 | C2: 2 | D2: 3 | E2: 4 | F2: 5 | G2: 6 | H2: 7 | I2: 8 | J2: 9 | K2: 10 | N2: Months to debt-free (this plan) | O2: =IF($L$14<=0,0,IFERROR(MATCH(0,$L$15:$L$374,0),999)) -> 31
A3: Sort key (internal) | B3: =IF(N('My Debts'!C7)<=0,9000000000+COLUMN(),N('My Debts'!C7)+COLUMN()/1000) -> 640.002 | C3: =IF(N('My Debts'!C8)<=0,9000000000+COLUMN(),N('My Debts'!C8)+COLUMN()/1000) -> 1200.003 | D3: =IF(N('My Debts'!C9)<=0,9000000000+COLUMN(),N('My Debts'!C9)+COLUMN()/1000) -> 2850.004 | E3: =IF(N('My Debts'!C10)<=0,9000000000+COLUMN(),N('My Debts'!C10)+COLUMN()/1000) -> 4100.005 | F3: =IF(N('My Debts'!C11)<=0,9000000000+COLUMN(),N('My Debts'!C11)+COLUMN()/1000) -> 9400.006 | G3: =IF(N('My Debts'!C12)<=0,9000000000+COLUMN(),N('My Debts'!C12)+COLUMN()/1000) -> 9000000007 | H3: =IF(N('My Debts'!C13)<=0,9000000000+COLUMN(),N('My Debts'!C13)+COLUMN()/1000) -> 9000000008 | I3: =IF(N('My Debts'!C14)<=0,9000000000+COLUMN(),N('My Debts'!C14)+COLUMN()/1000) -> 9000000009 | J3: =IF(N('My Debts'!C15)<=0,9000000000+COLUMN(),N('My Debts'!C15)+COLUMN()/1000) -> 9000000010 | K3: =IF(N('My Debts'!C16)<=0,9000000000+COLUMN(),N('My Debts'!C16)+COLUMN()/1000) -> 9000000011 | N3: Total interest (this plan) | O3: =SUM($M$15:$M$374) -> 3387.303
A4: Feeds from debt # | B4: =MATCH(SMALL($B$3:$K$3,B$2),$B$3:$K$3,0) -> 1 | C4: =MATCH(SMALL($B$3:$K$3,C$2),$B$3:$K$3,0) -> 2 | D4: =MATCH(SMALL($B$3:$K$3,D$2),$B$3:$K$3,0) -> 3 | E4: =MATCH(SMALL($B$3:$K$3,E$2),$B$3:$K$3,0) -> 4 | F4: =MATCH(SMALL($B$3:$K$3,F$2),$B$3:$K$3,0) -> 5 | G4: =MATCH(SMALL($B$3:$K$3,G$2),$B$3:$K$3,0) -> 6 | H4: =MATCH(SMALL($B$3:$K$3,H$2),$B$3:$K$3,0) -> 7 | I4: =MATCH(SMALL($B$3:$K$3,I$2),$B$3:$K$3,0) -> 8 | ... K4: =MATCH(SMALL($B$3:$K$3,K$2),$B$3:$K$3,0) -> 10 | N4: Months to debt-free (minimums only) | O4: =IF($L$14<=0,0,IFERROR(MATCH(0,$AS$15:$AS$374,0),999)) -> 42
A5: Start balance | B5: =ROUND(MAX(0,N(INDEX('My Debts'!$C$7:$C$16,B$4))),2) -> 640 | C5: =ROUND(MAX(0,N(INDEX('My Debts'!$C$7:$C$16,C$4))),2) -> 1200 | D5: =ROUND(MAX(0,N(INDEX('My Debts'!$C$7:$C$16,D$4))),2) -> 2850 | E5: =ROUND(MAX(0,N(INDEX('My Debts'!$C$7:$C$16,E$4))),2) -> 4100 | F5: =ROUND(MAX(0,N(INDEX('My Debts'!$C$7:$C$16,F$4))),2) -> 9400 | G5: =ROUND(MAX(0,N(INDEX('My Debts'!$C$7:$C$16,G$4))),2) -> 0 | H5: =ROUND(MAX(0,N(INDEX('My Debts'!$C$7:$C$16,H$4))),2) -> 0 | I5: =ROUND(MAX(0,N(INDEX('My Debts'!$C$7:$C$16,I$4))),2) -> 0 | ... K5: =ROUND(MAX(0,N(INDEX('My Debts'!$C$7:$C$16,K$4))),2) -> 0 | N5: Total interest (minimums only) | O5: =SUM($AT$15:$AT$374) -> 5459.5687
A6: Debt | B6: =IF(B$5<=0,"",T(INDEX('My Debts'!$B$7:$B$16,B$4))) -> Store card | C6: =IF(C$5<=0,"",T(INDEX('My Debts'!$B$7:$B$16,C$4))) -> Medical bill | D6: =IF(D$5<=0,"",T(INDEX('My Debts'!$B$7:$B$16,D$4))) -> Credit card A | E6: =IF(E$5<=0,"",T(INDEX('My Debts'!$B$7:$B$16,E$4))) -> Credit card B | F6: =IF(F$5<=0,"",T(INDEX('My Debts'!$B$7:$B$16,F$4))) -> Car loan | G6: =IF(G$5<=0,"",T(INDEX('My Debts'!$B$7:$B$16,G$4))) | H6: =IF(H$5<=0,"",T(INDEX('My Debts'!$B$7:$B$16,H$4))) | I6: =IF(I$5<=0,"",T(INDEX('My Debts'!$B$7:$B$16,I$4))) | ... K6: =IF(K$5<=0,"",T(INDEX('My Debts'!$B$7:$B$16,K$4)))
A7: APR | B7: =IF(B$5<=0,0,MAX(0,N(INDEX('My Debts'!$D$7:$D$16,B$4)))) -> 0.279 | C7: =IF(C$5<=0,0,MAX(0,N(INDEX('My Debts'!$D$7:$D$16,C$4)))) -> 0 | D7: =IF(D$5<=0,0,MAX(0,N(INDEX('My Debts'!$D$7:$D$16,D$4)))) -> 0.246 | E7: =IF(E$5<=0,0,MAX(0,N(INDEX('My Debts'!$D$7:$D$16,E$4)))) -> 0.219 | F7: =IF(F$5<=0,0,MAX(0,N(INDEX('My Debts'!$D$7:$D$16,F$4)))) -> 0.069 | G7: =IF(G$5<=0,0,MAX(0,N(INDEX('My Debts'!$D$7:$D$16,G$4)))) -> 0 | H7: =IF(H$5<=0,0,MAX(0,N(INDEX('My Debts'!$D$7:$D$16,H$4)))) -> 0 | I7: =IF(I$5<=0,0,MAX(0,N(INDEX('My Debts'!$D$7:$D$16,I$4)))) -> 0 | ... K7: =IF(K$5<=0,0,MAX(0,N(INDEX('My Debts'!$D$7:$D$16,K$4)))) -> 0
A8: Monthly rate | B8: =B$7/12 -> 0.02325 | C8: =C$7/12 -> 0 | D8: =D$7/12 -> 0.0205 | E8: =E$7/12 -> 0.01825 | F8: =F$7/12 -> 0.00575 | G8: =G$7/12 -> 0 | H8: =H$7/12 -> 0 | I8: =I$7/12 -> 0 | ... K8: =K$7/12 -> 0
A9: Min payment | B9: =IF(B$5<=0,0,MAX(0,N(INDEX('My Debts'!$E$7:$E$16,B$4)))) -> 35 | C9: =IF(C$5<=0,0,MAX(0,N(INDEX('My Debts'!$E$7:$E$16,C$4)))) -> 50 | D9: =IF(D$5<=0,0,MAX(0,N(INDEX('My Debts'!$E$7:$E$16,D$4)))) -> 75 | E9: =IF(E$5<=0,0,MAX(0,N(INDEX('My Debts'!$E$7:$E$16,E$4)))) -> 95 | F9: =IF(F$5<=0,0,MAX(0,N(INDEX('My Debts'!$E$7:$E$16,F$4)))) -> 310 | G9: =IF(G$5<=0,0,MAX(0,N(INDEX('My Debts'!$E$7:$E$16,G$4)))) -> 0 | H9: =IF(H$5<=0,0,MAX(0,N(INDEX('My Debts'!$E$7:$E$16,H$4)))) -> 0 | I9: =IF(I$5<=0,0,MAX(0,N(INDEX('My Debts'!$E$7:$E$16,I$4)))) -> 0 | ... K9: =IF(K$5<=0,0,MAX(0,N(INDEX('My Debts'!$E$7:$E$16,K$4)))) -> 0
A10: Paid off in month # | B10: =IF(B$5<=0,"",IFERROR(MATCH(0,B$15:B$374,0),999)) -> 4 | C10: =IF(C$5<=0,"",IFERROR(MATCH(0,C$15:C$374,0),999)) -> 8 | D10: =IF(D$5<=0,"",IFERROR(MATCH(0,D$15:D$374,0),999)) -> 18 | E10: =IF(E$5<=0,"",IFERROR(MATCH(0,E$15:E$374,0),999)) -> 28 | F10: =IF(F$5<=0,"",IFERROR(MATCH(0,F$15:F$374,0),999)) -> 31 | G10: =IF(G$5<=0,"",IFERROR(MATCH(0,G$15:G$374,0),999)) | H10: =IF(H$5<=0,"",IFERROR(MATCH(0,H$15:H$374,0),999)) | I10: =IF(I$5<=0,"",IFERROR(MATCH(0,I$15:I$374,0),999)) | ... K10: =IF(K$5<=0,"",IFERROR(MATCH(0,K$15:K$374,0),999))
A11: Monthly budget (minimums + extra) | B11: =MAX(0,N('My Debts'!$E$4))+SUM($B$9:$K$9) -> 715
A12: Budget if minimums only | B12: =SUM($B$9:$K$9) -> 565
A13: Month | B13: Bal 1 | C13: Bal 2 | D13: Bal 3 | E13: Bal 4 | F13: Bal 5 | G13: Bal 6 | H13: Bal 7 | I13: Bal 8 | J13: Bal 9 | K13: Bal 10 | L13: Total balance | M13: Interest | N13: Min due 1 | O13: Min due 2 | P13: Min due 3 | Q13: Min due 4 | R13: Min due 5 | S13: Min due 6 | T13: Min due 7 | U13: Min due 8 | V13: Min due 9 | W13: Min due 10 | X13: Pay 1 | Y13: Pay 2 | Z13: Pay 3 | AA13: Pay 4 | AB13: Pay 5 | AC13: Pay 6 | AD13: Pay 7 | AE13: Pay 8 | AF13: Pay 9 | AG13: Pay 10 | AI13: (min-only) Bal 1 | AJ13: (min-only) Bal 2 | AK13: (min-only) Bal 3 | AL13: (min-only) Bal 4 | AM13: (min-only) Bal 5 | AN13: (min-only) Bal 6 | AO13: (min-only) Bal 7 | AP13: (min-only) Bal 8 | AQ13: (min-only) Bal 9 | AR13: (min-only) Bal 10 | AS13: (min-only) Total | AT13: (min-only) Interest | AU13: (min-only) Min due 1 | AV13: (min-only) Min due 2 | AW13: (min-only) Min due 3 | AX13: (min-only) Min due 4 | AY13: (min-only) Min due 5 | AZ13: (min-only) Min due 6 | BA13: (min-only) Min due 7 | BB13: (min-only) Min due 8 | BC13: (min-only) Min due 9 | BD13: (min-only) Min due 10 | BE13: (min-only) Pay 1 | BF13: (min-only) Pay 2 | BG13: (min-only) Pay 3 | BH13: (min-only) Pay 4 | BI13: (min-only) Pay 5 | BJ13: (min-only) Pay 6 | BK13: (min-only) Pay 7 | BL13: (min-only) Pay 8 | BM13: (min-only) Pay 9 | BN13: (min-only) Pay 10
A14: 0 | B14: =B$5 -> 640 | C14: =C$5 -> 1200 | D14: =D$5 -> 2850 | E14: =E$5 -> 4100 | F14: =F$5 -> 9400 | G14: =G$5 -> 0 | H14: =H$5 -> 0 | I14: =I$5 -> 0 | ... K14: =K$5 -> 0 | L14: =SUM(B14:K14) -> 18190 | AI14: =B$5 -> 640 | AJ14: =C$5 -> 1200 | AK14: =D$5 -> 2850 | AL14: =E$5 -> 4100 | AM14: =F$5 -> 9400 | AN14: =G$5 -> 0 | AO14: =H$5 -> 0 | AP14: =I$5 -> 0 | ... AR14: =K$5 -> 0 | AS14: =SUM(AI14:AR14) -> 18190
A15: 1 | B15: =ROUND(MAX(0,B14*(1+B$8)-X15),2) -> 469.88 | C15: =ROUND(MAX(0,C14*(1+C$8)-Y15),2) -> 1150 | D15: =ROUND(MAX(0,D14*(1+D$8)-Z15),2) -> 2833.43 | E15: =ROUND(MAX(0,E14*(1+E$8)-AA15),2) -> 4079.83 | F15: =ROUND(MAX(0,F14*(1+F$8)-AB15),2) -> 9144.05 | G15: =ROUND(MAX(0,G14*(1+G$8)-AC15),2) -> 0 | H15: =ROUND(MAX(0,H14*(1+H$8)-AD15),2) -> 0 | I15: =ROUND(MAX(0,I14*(1+I$8)-AE15),2) -> 0 | ... K15: =ROUND(MAX(0,K14*(1+K$8)-AG15),2) -> 0 | L15: =SUM(B15:K15) -> 17677.19 | M15: =SUMPRODUCT(B14:K14,$B$8:$K$8) -> 202.18 | N15: =MIN(B14*(1+B$8),B$9) -> 35 | O15: =MIN(C14*(1+C$8),C$9) -> 50 | P15: =MIN(D14*(1+D$8),D$9) -> 75 | Q15: =MIN(E14*(1+E$8),E$9) -> 95 | R15: =MIN(F14*(1+F$8),F$9) -> 310 | S15: =MIN(G14*(1+G$8),G$9) -> 0 | T15: =MIN(H14*(1+H$8),H$9) -> 0 | U15: =MIN(I14*(1+I$8),I$9) -> 0 | ... W15: =MIN(K14*(1+K$8),K$9) -> 0 | X15: =MIN(B14*(1+B$8),MAX(N15,$B$11-SUM(O15:W15))) -> 185 | Y15: =MIN(C14*(1+C$8),MAX(O15,$B$11-SUM(X15:X15)-SUM(P15:W15))) -> 50 | Z15: =MIN(D14*(1+D$8),MAX(P15,$B$11-SUM(X15:Y15)-SUM(Q15:W15))) -> 75 | AA15: =MIN(E14*(1+E$8),MAX(Q15,$B$11-SUM(X15:Z15)-SUM(R15:W15))) -> 95 | AB15: =MIN(F14*(1+F$8),MAX(R15,$B$11-SUM(X15:AA15)-SUM(S15:W15))) -> 310 | AC15: =MIN(G14*(1+G$8),MAX(S15,$B$11-SUM(X15:AB15)-SUM(T15:W15))) -> 0 | AD15: =MIN(H14*(1+H$8),MAX(T15,$B$11-SUM(X15:AC15)-SUM(U15:W15))) -> 0 | AE15: =MIN(I14*(1+I$8),MAX(U15,$B$11-SUM(X15:AD15)-SUM(V15:W15))) -> 0 | AF15: =MIN(J14*(1+J$8),MAX(V15,$B$11-SUM(X15:AE15)-SUM(W15:W15))) -> 0 | AG15: =MIN(K14*(1+K$8),MAX(W15,$B$11-SUM(X15:AF15))) -> 0 | AI15: =ROUND(MAX(0,AI14*(1+B$8)-BE15),2) -> 619.88 | AJ15: =ROUND(MAX(0,AJ14*(1+C$8)-BF15),2) -> 1150 | AK15: =ROUND(MAX(0,AK14*(1+D$8)-BG15),2) -> 2833.43 | AL15: =ROUND(MAX(0,AL14*(1+E$8)-BH15),2) -> 4079.83 | AM15: =ROUND(MAX(0,AM14*(1+F$8)-BI15),2) -> 9144.05 | AN15: =ROUND(MAX(0,AN14*(1+G$8)-BJ15),2) -> 0 | AO15: =ROUND(MAX(0,AO14*(1+H$8)-BK15),2) -> 0 | AP15: =ROUND(MAX(0,AP14*(1+I$8)-BL15),2) -> 0 | ... AR15: =ROUND(MAX(0,AR14*(1+K$8)-BN15),2) -> 0 | AS15: =SUM(AI15:AR15) -> 17827.19 | AT15: =SUMPRODUCT(AI14:AR14,$B$8:$K$8) -> 202.18 | AU15: =MIN(AI14*(1+B$8),B$9) -> 35 | AV15: =MIN(AJ14*(1+C$8),C$9) -> 50 | AW15: =MIN(AK14*(1+D$8),D$9) -> 75 | AX15: =MIN(AL14*(1+E$8),E$9) -> 95 | AY15: =MIN(AM14*(1+F$8),F$9) -> 310 | AZ15: =MIN(AN14*(1+G$8),G$9) -> 0 | BA15: =MIN(AO14*(1+H$8),H$9) -> 0 | BB15: =MIN(AP14*(1+I$8),I$9) -> 0 | ... BD15: =MIN(AR14*(1+K$8),K$9) -> 0 | BE15: =MIN(AI14*(1+B$8),MAX(AU15,$B$12-SUM(AV15:BD15))) -> 35 | BF15: =MIN(AJ14*(1+C$8),MAX(AV15,$B$12-SUM(BE15:BE15)-SUM(AW15:BD15))) -> 50 | BG15: =MIN(AK14*(1+D$8),MAX(AW15,$B$12-SUM(BE15:BF15)-SUM(AX15:BD15))) -> 75 | BH15: =MIN(AL14*(1+E$8),MAX(AX15,$B$12-SUM(BE15:BG15)-SUM(AY15:BD15))) -> 95 | BI15: =MIN(AM14*(1+F$8),MAX(AY15,$B$12-SUM(BE15:BH15)-SUM(AZ15:BD15))) -> 310 | BJ15: =MIN(AN14*(1+G$8),MAX(AZ15,$B$12-SUM(BE15:BI15)-SUM(BA15:BD15))) -> 0 | BK15: =MIN(AO14*(1+H$8),MAX(BA15,$B$12-SUM(BE15:BJ15)-SUM(BB15:BD15))) -> 0 | BL15: =MIN(AP14*(1+I$8),MAX(BB15,$B$12-SUM(BE15:BK15)-SUM(BC15:BD15))) -> 0 | BM15: =MIN(AQ14*(1+J$8),MAX(BC15,$B$12-SUM(BE15:BL15)-SUM(BD15:BD15))) -> 0 | BN15: =MIN(AR14*(1+K$8),MAX(BD15,$B$12-SUM(BE15:BM15))) -> 0
A16: 2 | B16: =ROUND(MAX(0,B15*(1+B$8)-X16),2) -> 295.8 | C16: =ROUND(MAX(0,C15*(1+C$8)-Y16),2) -> 1100 | D16: =ROUND(MAX(0,D15*(1+D$8)-Z16),2) -> 2816.52 | E16: =ROUND(MAX(0,E15*(1+E$8)-AA16),2) -> 4059.29 | F16: =ROUND(MAX(0,F15*(1+F$8)-AB16),2) -> 8886.63 | G16: =ROUND(MAX(0,G15*(1+G$8)-AC16),2) -> 0 | H16: =ROUND(MAX(0,H15*(1+H$8)-AD16),2) -> 0 | I16: =ROUND(MAX(0,I15*(1+I$8)-AE16),2) -> 0 | ... K16: =ROUND(MAX(0,K15*(1+K$8)-AG16),2) -> 0 | L16: =SUM(B16:K16) -> 17158.24 | M16: =SUMPRODUCT(B15:K15,$B$8:$K$8) -> 196.04521 | N16: =MIN(B15*(1+B$8),B$9) -> 35 | O16: =MIN(C15*(1+C$8),C$9) -> 50 | P16: =MIN(D15*(1+D$8),D$9) -> 75 | Q16: =MIN(E15*(1+E$8),E$9) -> 95 | R16: =MIN(F15*(1+F$8),F$9) -> 310 | S16: =MIN(G15*(1+G$8),G$9) -> 0 | T16: =MIN(H15*(1+H$8),H$9) -> 0 | U16: =MIN(I15*(1+I$8),I$9) -> 0 | ... W16: =MIN(K15*(1+K$8),K$9) -> 0 | X16: =MIN(B15*(1+B$8),MAX(N16,$B$11-SUM(O16:W16))) -> 185 | Y16: =MIN(C15*(1+C$8),MAX(O16,$B$11-SUM(X16:X16)-SUM(P16:W16))) -> 50 | Z16: =MIN(D15*(1+D$8),MAX(P16,$B$11-SUM(X16:Y16)-SUM(Q16:W16))) -> 75 | AA16: =MIN(E15*(1+E$8),MAX(Q16,$B$11-SUM(X16:Z16)-SUM(R16:W16))) -> 95 | AB16: =MIN(F15*(1+F$8),MAX(R16,$B$11-SUM(X16:AA16)-SUM(S16:W16))) -> 310 | AC16: =MIN(G15*(1+G$8),MAX(S16,$B$11-SUM(X16:AB16)-SUM(T16:W16))) -> 0 | AD16: =MIN(H15*(1+H$8),MAX(T16,$B$11-SUM(X16:AC16)-SUM(U16:W16))) -> 0 | AE16: =MIN(I15*(1+I$8),MAX(U16,$B$11-SUM(X16:AD16)-SUM(V16:W16))) -> 0 | AF16: =MIN(J15*(1+J$8),MAX(V16,$B$11-SUM(X16:AE16)-SUM(W16:W16))) -> 0 | AG16: =MIN(K15*(1+K$8),MAX(W16,$B$11-SUM(X16:AF16))) -> 0 | AI16: =ROUND(MAX(0,AI15*(1+B$8)-BE16),2) -> 599.29 | AJ16: =ROUND(MAX(0,AJ15*(1+C$8)-BF16),2) -> 1100 | AK16: =ROUND(MAX(0,AK15*(1+D$8)-BG16),2) -> 2816.52 | AL16: =ROUND(MAX(0,AL15*(1+E$8)-BH16),2) -> 4059.29 | AM16: =ROUND(MAX(0,AM15*(1+F$8)-BI16),2) -> 8886.63 | AN16: =ROUND(MAX(0,AN15*(1+G$8)-BJ16),2) -> 0 | AO16: =ROUND(MAX(0,AO15*(1+H$8)-BK16),2) -> 0 | AP16: =ROUND(MAX(0,AP15*(1+I$8)-BL16),2) -> 0 | ... AR16: =ROUND(MAX(0,AR15*(1+K$8)-BN16),2) -> 0 | AS16: =SUM(AI16:AR16) -> 17461.73 | AT16: =SUMPRODUCT(AI15:AR15,$B$8:$K$8) -> 199.53271 | AU16: =MIN(AI15*(1+B$8),B$9) -> 35 | AV16: =MIN(AJ15*(1+C$8),C$9) -> 50 | AW16: =MIN(AK15*(1+D$8),D$9) -> 75 | AX16: =MIN(AL15*(1+E$8),E$9) -> 95 | AY16: =MIN(AM15*(1+F$8),F$9) -> 310 | AZ16: =MIN(AN15*(1+G$8),G$9) -> 0 | BA16: =MIN(AO15*(1+H$8),H$9) -> 0 | BB16: =MIN(AP15*(1+I$8),I$9) -> 0 | ... BD16: =MIN(AR15*(1+K$8),K$9) -> 0 | BE16: =MIN(AI15*(1+B$8),MAX(AU16,$B$12-SUM(AV16:BD16))) -> 35 | BF16: =MIN(AJ15*(1+C$8),MAX(AV16,$B$12-SUM(BE16:BE16)-SUM(AW16:BD16))) -> 50 | BG16: =MIN(AK15*(1+D$8),MAX(AW16,$B$12-SUM(BE16:BF16)-SUM(AX16:BD16))) -> 75 | BH16: =MIN(AL15*(1+E$8),MAX(AX16,$B$12-SUM(BE16:BG16)-SUM(AY16:BD16))) -> 95 | BI16: =MIN(AM15*(1+F$8),MAX(AY16,$B$12-SUM(BE16:BH16)-SUM(AZ16:BD16))) -> 310 | BJ16: =MIN(AN15*(1+G$8),MAX(AZ16,$B$12-SUM(BE16:BI16)-SUM(BA16:BD16))) -> 0 | BK16: =MIN(AO15*(1+H$8),MAX(BA16,$B$12-SUM(BE16:BJ16)-SUM(BB16:BD16))) -> 0 | BL16: =MIN(AP15*(1+I$8),MAX(BB16,$B$12-SUM(BE16:BK16)-SUM(BC16:BD16))) -> 0 | BM16: =MIN(AQ15*(1+J$8),MAX(BC16,$B$12-SUM(BE16:BL16)-SUM(BD16:BD16))) -> 0 | BN16: =MIN(AR15*(1+K$8),MAX(BD16,$B$12-SUM(BE16:BM16))) -> 0
A17: 3 | B17: =ROUND(MAX(0,B16*(1+B$8)-X17),2) -> 117.68 | C17: =ROUND(MAX(0,C16*(1+C$8)-Y17),2) -> 1050 | D17: =ROUND(MAX(0,D16*(1+D$8)-Z17),2) -> 2799.26 | E17: =ROUND(MAX(0,E16*(1+E$8)-AA17),2) -> 4038.37 | F17: =ROUND(MAX(0,F16*(1+F$8)-AB17),2) -> 8627.73 | G17: =ROUND(MAX(0,G16*(1+G$8)-AC17),2) -> 0 | H17: =ROUND(MAX(0,H16*(1+H$8)-AD17),2) -> 0 | I17: =ROUND(MAX(0,I16*(1+I$8)-AE17),2) -> 0 | ... K17: =ROUND(MAX(0,K16*(1+K$8)-AG17),2) -> 0 | L17: =SUM(B17:K17) -> 16633.04 | M17: =SUMPRODUCT(B16:K16,$B$8:$K$8) -> 189.79618 | N17: =MIN(B16*(1+B$8),B$9) -> 35 | O17: =MIN(C16*(1+C$8),C$9) -> 50 | P17: =MIN(D16*(1+D$8),D$9) -> 75 | Q17: =MIN(E16*(1+E$8),E$9) -> 95 | R17: =MIN(F16*(1+F$8),F$9) -> 310 | S17: =MIN(G16*(1+G$8),G$9) -> 0 | T17: =MIN(H16*(1+H$8),H$9) -> 0 | U17: =MIN(I16*(1+I$8),I$9) -> 0 | ... W17: =MIN(K16*(1+K$8),K$9) -> 0 | X17: =MIN(B16*(1+B$8),MAX(N17,$B$11-SUM(O17:W17))) -> 185 | Y17: =MIN(C16*(1+C$8),MAX(O17,$B$11-SUM(X17:X17)-SUM(P17:W17))) -> 50 | Z17: =MIN(D16*(1+D$8),MAX(P17,$B$11-SUM(X17:Y17)-SUM(Q17:W17))) -> 75 | AA17: =MIN(E16*(1+E$8),MAX(Q17,$B$11-SUM(X17:Z17)-SUM(R17:W17))) -> 95 | AB17: =MIN(F16*(1+F$8),MAX(R17,$B$11-SUM(X17:AA17)-SUM(S17:W17))) -> 310 | AC17: =MIN(G16*(1+G$8),MAX(S17,$B$11-SUM(X17:AB17)-SUM(T17:W17))) -> 0 | AD17: =MIN(H16*(1+H$8),MAX(T17,$B$11-SUM(X17:AC17)-SUM(U17:W17))) -> 0 | AE17: =MIN(I16*(1+I$8),MAX(U17,$B$11-SUM(X17:AD17)-SUM(V17:W17))) -> 0 | AF17: =MIN(J16*(1+J$8),MAX(V17,$B$11-SUM(X17:AE17)-SUM(W17:W17))) -> 0 | AG17: =MIN(K16*(1+K$8),MAX(W17,$B$11-SUM(X17:AF17))) -> 0 | AI17: =ROUND(MAX(0,AI16*(1+B$8)-BE17),2) -> 578.22 | AJ17: =ROUND(MAX(0,AJ16*(1+C$8)-BF17),2) -> 1050 | AK17: =ROUND(MAX(0,AK16*(1+D$8)-BG17),2) -> 2799.26 | AL17: =ROUND(MAX(0,AL16*(1+E$8)-BH17),2) -> 4038.37 | AM17: =ROUND(MAX(0,AM16*(1+F$8)-BI17),2) -> 8627.73 | AN17: =ROUND(MAX(0,AN16*(1+G$8)-BJ17),2) -> 0 | AO17: =ROUND(MAX(0,AO16*(1+H$8)-BK17),2) -> 0 | AP17: =ROUND(MAX(0,AP16*(1+I$8)-BL17),2) -> 0 | ... AR17: =ROUND(MAX(0,AR16*(1+K$8)-BN17),2) -> 0 | AS17: =SUM(AI17:AR17) -> 17093.58 | AT17: =SUMPRODUCT(AI16:AR16,$B$8:$K$8) -> 196.85232 | AU17: =MIN(AI16*(1+B$8),B$9) -> 35 | AV17: =MIN(AJ16*(1+C$8),C$9) -> 50 | AW17: =MIN(AK16*(1+D$8),D$9) -> 75 | AX17: =MIN(AL16*(1+E$8),E$9) -> 95 | AY17: =MIN(AM16*(1+F$8),F$9) -> 310 | AZ17: =MIN(AN16*(1+G$8),G$9) -> 0 | BA17: =MIN(AO16*(1+H$8),H$9) -> 0 | BB17: =MIN(AP16*(1+I$8),I$9) -> 0 | ... BD17: =MIN(AR16*(1+K$8),K$9) -> 0 | BE17: =MIN(AI16*(1+B$8),MAX(AU17,$B$12-SUM(AV17:BD17))) -> 35 | BF17: =MIN(AJ16*(1+C$8),MAX(AV17,$B$12-SUM(BE17:BE17)-SUM(AW17:BD17))) -> 50 | BG17: =MIN(AK16*(1+D$8),MAX(AW17,$B$12-SUM(BE17:BF17)-SUM(AX17:BD17))) -> 75 | BH17: =MIN(AL16*(1+E$8),MAX(AX17,$B$12-SUM(BE17:BG17)-SUM(AY17:BD17))) -> 95 | BI17: =MIN(AM16*(1+F$8),MAX(AY17,$B$12-SUM(BE17:BH17)-SUM(AZ17:BD17))) -> 310 | BJ17: =MIN(AN16*(1+G$8),MAX(AZ17,$B$12-SUM(BE17:BI17)-SUM(BA17:BD17))) -> 0 | BK17: =MIN(AO16*(1+H$8),MAX(BA17,$B$12-SUM(BE17:BJ17)-SUM(BB17:BD17))) -> 0 | BL17: =MIN(AP16*(1+I$8),MAX(BB17,$B$12-SUM(BE17:BK17)-SUM(BC17:BD17))) -> 0 | BM17: =MIN(AQ16*(1+J$8),MAX(BC17,$B$12-SUM(BE17:BL17)-SUM(BD17:BD17))) -> 0 | BN17: =MIN(AR16*(1+K$8),MAX(BD17,$B$12-SUM(BE17:BM17))) -> 0
A18: 4 | B18: =ROUND(MAX(0,B17*(1+B$8)-X18),2) -> 0 | C18: =ROUND(MAX(0,C17*(1+C$8)-Y18),2) -> 935.42 | D18: =ROUND(MAX(0,D17*(1+D$8)-Z18),2) -> 2781.64 | E18: =ROUND(MAX(0,E17*(1+E$8)-AA18),2) -> 4017.07 | F18: =ROUND(MAX(0,F17*(1+F$8)-AB18),2) -> 8367.34 | G18: =ROUND(MAX(0,G17*(1+G$8)-AC18),2) -> 0 | H18: =ROUND(MAX(0,H17*(1+H$8)-AD18),2) -> 0 | I18: =ROUND(MAX(0,I17*(1+I$8)-AE18),2) -> 0 | ... K18: =ROUND(MAX(0,K17*(1+K$8)-AG18),2) -> 0 | L18: =SUM(B18:K18) -> 16101.47 | M18: =SUMPRODUCT(B17:K17,$B$8:$K$8) -> 183.43059 | N18: =MIN(B17*(1+B$8),B$9) -> 35 | O18: =MIN(C17*(1+C$8),C$9) -> 50 | P18: =MIN(D17*(1+D$8),D$9) -> 75 | Q18: =MIN(E17*(1+E$8),E$9) -> 95 | R18: =MIN(F17*(1+F$8),F$9) -> 310 | S18: =MIN(G17*(1+G$8),G$9) -> 0 | T18: =MIN(H17*(1+H$8),H$9) -> 0 | U18: =MIN(I17*(1+I$8),I$9) -> 0 | ... W18: =MIN(K17*(1+K$8),K$9) -> 0 | X18: =MIN(B17*(1+B$8),MAX(N18,$B$11-SUM(O18:W18))) -> 120.41606 | Y18: =MIN(C17*(1+C$8),MAX(O18,$B$11-SUM(X18:X18)-SUM(P18:W18))) -> 114.58394 | Z18: =MIN(D17*(1+D$8),MAX(P18,$B$11-SUM(X18:Y18)-SUM(Q18:W18))) -> 75 | AA18: =MIN(E17*(1+E$8),MAX(Q18,$B$11-SUM(X18:Z18)-SUM(R18:W18))) -> 95 | AB18: =MIN(F17*(1+F$8),MAX(R18,$B$11-SUM(X18:AA18)-SUM(S18:W18))) -> 310 | AC18: =MIN(G17*(1+G$8),MAX(S18,$B$11-SUM(X18:AB18)-SUM(T18:W18))) -> 0 | AD18: =MIN(H17*(1+H$8),MAX(T18,$B$11-SUM(X18:AC18)-SUM(U18:W18))) -> 0 | AE18: =MIN(I17*(1+I$8),MAX(U18,$B$11-SUM(X18:AD18)-SUM(V18:W18))) -> 0 | AF18: =MIN(J17*(1+J$8),MAX(V18,$B$11-SUM(X18:AE18)-SUM(W18:W18))) -> 0 | AG18: =MIN(K17*(1+K$8),MAX(W18,$B$11-SUM(X18:AF18))) -> 0 | AI18: =ROUND(MAX(0,AI17*(1+B$8)-BE18),2) -> 556.66 | AJ18: =ROUND(MAX(0,AJ17*(1+C$8)-BF18),2) -> 1000 | AK18: =ROUND(MAX(0,AK17*(1+D$8)-BG18),2) -> 2781.64 | AL18: =ROUND(MAX(0,AL17*(1+E$8)-BH18),2) -> 4017.07 | AM18: =ROUND(MAX(0,AM17*(1+F$8)-BI18),2) -> 8367.34 | AN18: =ROUND(MAX(0,AN17*(1+G$8)-BJ18),2) -> 0 | AO18: =ROUND(MAX(0,AO17*(1+H$8)-BK18),2) -> 0 | AP18: =ROUND(MAX(0,AP17*(1+I$8)-BL18),2) -> 0 | ... AR18: =ROUND(MAX(0,AR17*(1+K$8)-BN18),2) -> 0 | AS18: =SUM(AI18:AR18) -> 16722.71 | AT18: =SUMPRODUCT(AI17:AR17,$B$8:$K$8) -> 194.13815 | AU18: =MIN(AI17*(1+B$8),B$9) -> 35 | AV18: =MIN(AJ17*(1+C$8),C$9) -> 50 | AW18: =MIN(AK17*(1+D$8),D$9) -> 75 | AX18: =MIN(AL17*(1+E$8),E$9) -> 95 | AY18: =MIN(AM17*(1+F$8),F$9) -> 310 | AZ18: =MIN(AN17*(1+G$8),G$9) -> 0 | BA18: =MIN(AO17*(1+H$8),H$9) -> 0 | BB18: =MIN(AP17*(1+I$8),I$9) -> 0 | ... BD18: =MIN(AR17*(1+K$8),K$9) -> 0 | BE18: =MIN(AI17*(1+B$8),MAX(AU18,$B$12-SUM(AV18:BD18))) -> 35 | BF18: =MIN(AJ17*(1+C$8),MAX(AV18,$B$12-SUM(BE18:BE18)-SUM(AW18:BD18))) -> 50 | BG18: =MIN(AK17*(1+D$8),MAX(AW18,$B$12-SUM(BE18:BF18)-SUM(AX18:BD18))) -> 75 | BH18: =MIN(AL17*(1+E$8),MAX(AX18,$B$12-SUM(BE18:BG18)-SUM(AY18:BD18))) -> 95 | BI18: =MIN(AM17*(1+F$8),MAX(AY18,$B$12-SUM(BE18:BH18)-SUM(AZ18:BD18))) -> 310 | BJ18: =MIN(AN17*(1+G$8),MAX(AZ18,$B$12-SUM(BE18:BI18)-SUM(BA18:BD18))) -> 0 | BK18: =MIN(AO17*(1+H$8),MAX(BA18,$B$12-SUM(BE18:BJ18)-SUM(BB18:BD18))) -> 0 | BL18: =MIN(AP17*(1+I$8),MAX(BB18,$B$12-SUM(BE18:BK18)-SUM(BC18:BD18))) -> 0 | BM18: =MIN(AQ17*(1+J$8),MAX(BC18,$B$12-SUM(BE18:BL18)-SUM(BD18:BD18))) -> 0 | BN18: =MIN(AR17*(1+K$8),MAX(BD18,$B$12-SUM(BE18:BM18))) -> 0
A19: 5 | B19: =ROUND(MAX(0,B18*(1+B$8)-X19),2) -> 0 | C19: =ROUND(MAX(0,C18*(1+C$8)-Y19),2) -> 700.42 | D19: =ROUND(MAX(0,D18*(1+D$8)-Z19),2) -> 2763.66 | E19: =ROUND(MAX(0,E18*(1+E$8)-AA19),2) -> 3995.38 | F19: =ROUND(MAX(0,F18*(1+F$8)-AB19),2) -> 8105.45 | G19: =ROUND(MAX(0,G18*(1+G$8)-AC19),2) -> 0 | H19: =ROUND(MAX(0,H18*(1+H$8)-AD19),2) -> 0 | I19: =ROUND(MAX(0,I18*(1+I$8)-AE19),2) -> 0 | ... K19: =ROUND(MAX(0,K18*(1+K$8)-AG19),2) -> 0 | L19: =SUM(B19:K19) -> 15564.91 | M19: =SUMPRODUCT(B18:K18,$B$8:$K$8) -> 178.44735 | N19: =MIN(B18*(1+B$8),B$9) -> 0 | O19: =MIN(C18*(1+C$8),C$9) -> 50 | P19: =MIN(D18*(1+D$8),D$9) -> 75 | Q19: =MIN(E18*(1+E$8),E$9) -> 95 | R19: =MIN(F18*(1+F$8),F$9) -> 310 | S19: =MIN(G18*(1+G$8),G$9) -> 0 | T19: =MIN(H18*(1+H$8),H$9) -> 0 | U19: =MIN(I18*(1+I$8),I$9) -> 0 | ... W19: =MIN(K18*(1+K$8),K$9) -> 0 | X19: =MIN(B18*(1+B$8),MAX(N19,$B$11-SUM(O19:W19))) -> 0 | Y19: =MIN(C18*(1+C$8),MAX(O19,$B$11-SUM(X19:X19)-SUM(P19:W19))) -> 235 | Z19: =MIN(D18*(1+D$8),MAX(P19,$B$11-SUM(X19:Y19)-SUM(Q19:W19))) -> 75 | AA19: =MIN(E18*(1+E$8),MAX(Q19,$B$11-SUM(X19:Z19)-SUM(R19:W19))) -> 95 | AB19: =MIN(F18*(1+F$8),MAX(R19,$B$11-SUM(X19:AA19)-SUM(S19:W19))) -> 310 | AC19: =MIN(G18*(1+G$8),MAX(S19,$B$11-SUM(X19:AB19)-SUM(T19:W19))) -> 0 | AD19: =MIN(H18*(1+H$8),MAX(T19,$B$11-SUM(X19:AC19)-SUM(U19:W19))) -> 0 | AE19: =MIN(I18*(1+I$8),MAX(U19,$B$11-SUM(X19:AD19)-SUM(V19:W19))) -> 0 | AF19: =MIN(J18*(1+J$8),MAX(V19,$B$11-SUM(X19:AE19)-SUM(W19:W19))) -> 0 | AG19: =MIN(K18*(1+K$8),MAX(W19,$B$11-SUM(X19:AF19))) -> 0 | AI19: =ROUND(MAX(0,AI18*(1+B$8)-BE19),2) -> 534.6 | AJ19: =ROUND(MAX(0,AJ18*(1+C$8)-BF19),2) -> 950 | AK19: =ROUND(MAX(0,AK18*(1+D$8)-BG19),2) -> 2763.66 | AL19: =ROUND(MAX(0,AL18*(1+E$8)-BH19),2) -> 3995.38 | AM19: =ROUND(MAX(0,AM18*(1+F$8)-BI19),2) -> 8105.45 | AN19: =ROUND(MAX(0,AN18*(1+G$8)-BJ19),2) -> 0 | AO19: =ROUND(MAX(0,AO18*(1+H$8)-BK19),2) -> 0 | AP19: =ROUND(MAX(0,AP18*(1+I$8)-BL19),2) -> 0 | ... AR19: =ROUND(MAX(0,AR18*(1+K$8)-BN19),2) -> 0 | AS19: =SUM(AI19:AR19) -> 16349.09 | AT19: =SUMPRODUCT(AI18:AR18,$B$8:$K$8) -> 191.3897 | AU19: =MIN(AI18*(1+B$8),B$9) -> 35 | AV19: =MIN(AJ18*(1+C$8),C$9) -> 50 | AW19: =MIN(AK18*(1+D$8),D$9) -> 75 | AX19: =MIN(AL18*(1+E$8),E$9) -> 95 | AY19: =MIN(AM18*(1+F$8),F$9) -> 310 | AZ19: =MIN(AN18*(1+G$8),G$9) -> 0 | BA19: =MIN(AO18*(1+H$8),H$9) -> 0 | BB19: =MIN(AP18*(1+I$8),I$9) -> 0 | ... BD19: =MIN(AR18*(1+K$8),K$9) -> 0 | BE19: =MIN(AI18*(1+B$8),MAX(AU19,$B$12-SUM(AV19:BD19))) -> 35 | BF19: =MIN(AJ18*(1+C$8),MAX(AV19,$B$12-SUM(BE19:BE19)-SUM(AW19:BD19))) -> 50 | BG19: =MIN(AK18*(1+D$8),MAX(AW19,$B$12-SUM(BE19:BF19)-SUM(AX19:BD19))) -> 75 | BH19: =MIN(AL18*(1+E$8),MAX(AX19,$B$12-SUM(BE19:BG19)-SUM(AY19:BD19))) -> 95 | BI19: =MIN(AM18*(1+F$8),MAX(AY19,$B$12-SUM(BE19:BH19)-SUM(AZ19:BD19))) -> 310 | BJ19: =MIN(AN18*(1+G$8),MAX(AZ19,$B$12-SUM(BE19:BI19)-SUM(BA19:BD19))) -> 0 | BK19: =MIN(AO18*(1+H$8),MAX(BA19,$B$12-SUM(BE19:BJ19)-SUM(BB19:BD19))) -> 0 | BL19: =MIN(AP18*(1+I$8),MAX(BB19,$B$12-SUM(BE19:BK19)-SUM(BC19:BD19))) -> 0 | BM19: =MIN(AQ18*(1+J$8),MAX(BC19,$B$12-SUM(BE19:BL19)-SUM(BD19:BD19))) -> 0 | BN19: =MIN(AR18*(1+K$8),MAX(BD19,$B$12-SUM(BE19:BM19))) -> 0
A20: 6 | B20: =ROUND(MAX(0,B19*(1+B$8)-X20),2) -> 0 | C20: =ROUND(MAX(0,C19*(1+C$8)-Y20),2) -> 465.42 | D20: =ROUND(MAX(0,D19*(1+D$8)-Z20),2) -> 2745.32 | E20: =ROUND(MAX(0,E19*(1+E$8)-AA20),2) -> 3973.3 | F20: =ROUND(MAX(0,F19*(1+F$8)-AB20),2) -> 7842.06 | G20: =ROUND(MAX(0,G19*(1+G$8)-AC20),2) -> 0 | H20: =ROUND(MAX(0,H19*(1+H$8)-AD20),2) -> 0 | I20: =ROUND(MAX(0,I19*(1+I$8)-AE20),2) -> 0 | ... K20: =ROUND(MAX(0,K19*(1+K$8)-AG20),2) -> 0 | L20: =SUM(B20:K20) -> 15026.1 | M20: =SUMPRODUCT(B19:K19,$B$8:$K$8) -> 176.17705 | N20: =MIN(B19*(1+B$8),B$9) -> 0 | O20: =MIN(C19*(1+C$8),C$9) -> 50 | P20: =MIN(D19*(1+D$8),D$9) -> 75 | Q20: =MIN(E19*(1+E$8),E$9) -> 95 | R20: =MIN(F19*(1+F$8),F$9) -> 310 | S20: =MIN(G19*(1+G$8),G$9) -> 0 | T20: =MIN(H19*(1+H$8),H$9) -> 0 | U20: =MIN(I19*(1+I$8),I$9) -> 0 | ... W20: =MIN(K19*(1+K$8),K$9) -> 0 | X20: =MIN(B19*(1+B$8),MAX(N20,$B$11-SUM(O20:W20))) -> 0 | Y20: =MIN(C19*(1+C$8),MAX(O20,$B$11-SUM(X20:X20)-SUM(P20:W20))) -> 235 | Z20: =MIN(D19*(1+D$8),MAX(P20,$B$11-SUM(X20:Y20)-SUM(Q20:W20))) -> 75 | AA20: =MIN(E19*(1+E$8),MAX(Q20,$B$11-SUM(X20:Z20)-SUM(R20:W20))) -> 95 | AB20: =MIN(F19*(1+F$8),MAX(R20,$B$11-SUM(X20:AA20)-SUM(S20:W20))) -> 310 | AC20: =MIN(G19*(1+G$8),MAX(S20,$B$11-SUM(X20:AB20)-SUM(T20:W20))) -> 0 | AD20: =MIN(H19*(1+H$8),MAX(T20,$B$11-SUM(X20:AC20)-SUM(U20:W20))) -> 0 | AE20: =MIN(I19*(1+I$8),MAX(U20,$B$11-SUM(X20:AD20)-SUM(V20:W20))) -> 0 | AF20: =MIN(J19*(1+J$8),MAX(V20,$B$11-SUM(X20:AE20)-SUM(W20:W20))) -> 0 | AG20: =MIN(K19*(1+K$8),MAX(W20,$B$11-SUM(X20:AF20))) -> 0 | AI20: =ROUND(MAX(0,AI19*(1+B$8)-BE20),2) -> 512.03 | AJ20: =ROUND(MAX(0,AJ19*(1+C$8)-BF20),2) -> 900 | AK20: =ROUND(MAX(0,AK19*(1+D$8)-BG20),2) -> 2745.32 | AL20: =ROUND(MAX(0,AL19*(1+E$8)-BH20),2) -> 3973.3 | AM20: =ROUND(MAX(0,AM19*(1+F$8)-BI20),2) -> 7842.06 | AN20: =ROUND(MAX(0,AN19*(1+G$8)-BJ20),2) -> 0 | AO20: =ROUND(MAX(0,AO19*(1+H$8)-BK20),2) -> 0 | AP20: =ROUND(MAX(0,AP19*(1+I$8)-BL20),2) -> 0 | ... AR20: =ROUND(MAX(0,AR19*(1+K$8)-BN20),2) -> 0 | AS20: =SUM(AI20:AR20) -> 15972.71 | AT20: =SUMPRODUCT(AI19:AR19,$B$8:$K$8) -> 188.6065 | AU20: =MIN(AI19*(1+B$8),B$9) -> 35 | AV20: =MIN(AJ19*(1+C$8),C$9) -> 50 | AW20: =MIN(AK19*(1+D$8),D$9) -> 75 | AX20: =MIN(AL19*(1+E$8),E$9) -> 95 | AY20: =MIN(AM19*(1+F$8),F$9) -> 310 | AZ20: =MIN(AN19*(1+G$8),G$9) -> 0 | BA20: =MIN(AO19*(1+H$8),H$9) -> 0 | BB20: =MIN(AP19*(1+I$8),I$9) -> 0 | ... BD20: =MIN(AR19*(1+K$8),K$9) -> 0 | BE20: =MIN(AI19*(1+B$8),MAX(AU20,$B$12-SUM(AV20:BD20))) -> 35 | BF20: =MIN(AJ19*(1+C$8),MAX(AV20,$B$12-SUM(BE20:BE20)-SUM(AW20:BD20))) -> 50 | BG20: =MIN(AK19*(1+D$8),MAX(AW20,$B$12-SUM(BE20:BF20)-SUM(AX20:BD20))) -> 75 | BH20: =MIN(AL19*(1+E$8),MAX(AX20,$B$12-SUM(BE20:BG20)-SUM(AY20:BD20))) -> 95 | BI20: =MIN(AM19*(1+F$8),MAX(AY20,$B$12-SUM(BE20:BH20)-SUM(AZ20:BD20))) -> 310 | BJ20: =MIN(AN19*(1+G$8),MAX(AZ20,$B$12-SUM(BE20:BI20)-SUM(BA20:BD20))) -> 0 | BK20: =MIN(AO19*(1+H$8),MAX(BA20,$B$12-SUM(BE20:BJ20)-SUM(BB20:BD20))) -> 0 | BL20: =MIN(AP19*(1+I$8),MAX(BB20,$B$12-SUM(BE20:BK20)-SUM(BC20:BD20))) -> 0 | BM20: =MIN(AQ19*(1+J$8),MAX(BC20,$B$12-SUM(BE20:BL20)-SUM(BD20:BD20))) -> 0 | BN20: =MIN(AR19*(1+K$8),MAX(BD20,$B$12-SUM(BE20:BM20))) -> 0
A21: 7 | B21: =ROUND(MAX(0,B20*(1+B$8)-X21),2) -> 0 | C21: =ROUND(MAX(0,C20*(1+C$8)-Y21),2) -> 230.42 | D21: =ROUND(MAX(0,D20*(1+D$8)-Z21),2) -> 2726.6 | E21: =ROUND(MAX(0,E20*(1+E$8)-AA21),2) -> 3950.81 | F21: =ROUND(MAX(0,F20*(1+F$8)-AB21),2) -> 7577.15 | G21: =ROUND(MAX(0,G20*(1+G$8)-AC21),2) -> 0 | H21: =ROUND(MAX(0,H20*(1+H$8)-AD21),2) -> 0 | I21: =ROUND(MAX(0,I20*(1+I$8)-AE21),2) -> 0 | ... K21: =ROUND(MAX(0,K20*(1+K$8)-AG21),2) -> 0 | L21: =SUM(B21:K21) -> 14484.98 | M21: =SUMPRODUCT(B20:K20,$B$8:$K$8) -> 173.88363 | N21: =MIN(B20*(1+B$8),B$9) -> 0 | O21: =MIN(C20*(1+C$8),C$9) -> 50 | P21: =MIN(D20*(1+D$8),D$9) -> 75 | Q21: =MIN(E20*(1+E$8),E$9) -> 95 | R21: =MIN(F20*(1+F$8),F$9) -> 310 | S21: =MIN(G20*(1+G$8),G$9) -> 0 | T21: =MIN(H20*(1+H$8),H$9) -> 0 | U21: =MIN(I20*(1+I$8),I$9) -> 0 | ... W21: =MIN(K20*(1+K$8),K$9) -> 0 | X21: =MIN(B20*(1+B$8),MAX(N21,$B$11-SUM(O21:W21))) -> 0 | Y21: =MIN(C20*(1+C$8),MAX(O21,$B$11-SUM(X21:X21)-SUM(P21:W21))) -> 235 | Z21: =MIN(D20*(1+D$8),MAX(P21,$B$11-SUM(X21:Y21)-SUM(Q21:W21))) -> 75 | AA21: =MIN(E20*(1+E$8),MAX(Q21,$B$11-SUM(X21:Z21)-SUM(R21:W21))) -> 95 | AB21: =MIN(F20*(1+F$8),MAX(R21,$B$11-SUM(X21:AA21)-SUM(S21:W21))) -> 310 | AC21: =MIN(G20*(1+G$8),MAX(S21,$B$11-SUM(X21:AB21)-SUM(T21:W21))) -> 0 | AD21: =MIN(H20*(1+H$8),MAX(T21,$B$11-SUM(X21:AC21)-SUM(U21:W21))) -> 0 | AE21: =MIN(I20*(1+I$8),MAX(U21,$B$11-SUM(X21:AD21)-SUM(V21:W21))) -> 0 | AF21: =MIN(J20*(1+J$8),MAX(V21,$B$11-SUM(X21:AE21)-SUM(W21:W21))) -> 0 | AG21: =MIN(K20*(1+K$8),MAX(W21,$B$11-SUM(X21:AF21))) -> 0 | AI21: =ROUND(MAX(0,AI20*(1+B$8)-BE21),2) -> 488.93 | AJ21: =ROUND(MAX(0,AJ20*(1+C$8)-BF21),2) -> 850 | AK21: =ROUND(MAX(0,AK20*(1+D$8)-BG21),2) -> 2726.6 | AL21: =ROUND(MAX(0,AL20*(1+E$8)-BH21),2) -> 3950.81 | AM21: =ROUND(MAX(0,AM20*(1+F$8)-BI21),2) -> 7577.15 | AN21: =ROUND(MAX(0,AN20*(1+G$8)-BJ21),2) -> 0 | AO21: =ROUND(MAX(0,AO20*(1+H$8)-BK21),2) -> 0 | AP21: =ROUND(MAX(0,AP20*(1+I$8)-BL21),2) -> 0 | ... AR21: =ROUND(MAX(0,AR20*(1+K$8)-BN21),2) -> 0 | AS21: =SUM(AI21:AR21) -> 15593.49 | AT21: =SUMPRODUCT(AI20:AR20,$B$8:$K$8) -> 185.78833 | AU21: =MIN(AI20*(1+B$8),B$9) -> 35 | AV21: =MIN(AJ20*(1+C$8),C$9) -> 50 | AW21: =MIN(AK20*(1+D$8),D$9) -> 75 | AX21: =MIN(AL20*(1+E$8),E$9) -> 95 | AY21: =MIN(AM20*(1+F$8),F$9) -> 310 | AZ21: =MIN(AN20*(1+G$8),G$9) -> 0 | BA21: =MIN(AO20*(1+H$8),H$9) -> 0 | BB21: =MIN(AP20*(1+I$8),I$9) -> 0 | ... BD21: =MIN(AR20*(1+K$8),K$9) -> 0 | BE21: =MIN(AI20*(1+B$8),MAX(AU21,$B$12-SUM(AV21:BD21))) -> 35 | BF21: =MIN(AJ20*(1+C$8),MAX(AV21,$B$12-SUM(BE21:BE21)-SUM(AW21:BD21))) -> 50 | BG21: =MIN(AK20*(1+D$8),MAX(AW21,$B$12-SUM(BE21:BF21)-SUM(AX21:BD21))) -> 75 | BH21: =MIN(AL20*(1+E$8),MAX(AX21,$B$12-SUM(BE21:BG21)-SUM(AY21:BD21))) -> 95 | BI21: =MIN(AM20*(1+F$8),MAX(AY21,$B$12-SUM(BE21:BH21)-SUM(AZ21:BD21))) -> 310 | BJ21: =MIN(AN20*(1+G$8),MAX(AZ21,$B$12-SUM(BE21:BI21)-SUM(BA21:BD21))) -> 0 | BK21: =MIN(AO20*(1+H$8),MAX(BA21,$B$12-SUM(BE21:BJ21)-SUM(BB21:BD21))) -> 0 | BL21: =MIN(AP20*(1+I$8),MAX(BB21,$B$12-SUM(BE21:BK21)-SUM(BC21:BD21))) -> 0 | BM21: =MIN(AQ20*(1+J$8),MAX(BC21,$B$12-SUM(BE21:BL21)-SUM(BD21:BD21))) -> 0 | BN21: =MIN(AR20*(1+K$8),MAX(BD21,$B$12-SUM(BE21:BM21))) -> 0
A22: 8 | B22: =ROUND(MAX(0,B21*(1+B$8)-X22),2) -> 0 | C22: =ROUND(MAX(0,C21*(1+C$8)-Y22),2) -> 0 | D22: =ROUND(MAX(0,D21*(1+D$8)-Z22),2) -> 2702.92 | E22: =ROUND(MAX(0,E21*(1+E$8)-AA22),2) -> 3927.91 | F22: =ROUND(MAX(0,F21*(1+F$8)-AB22),2) -> 7310.72 | G22: =ROUND(MAX(0,G21*(1+G$8)-AC22),2) -> 0 | H22: =ROUND(MAX(0,H21*(1+H$8)-AD22),2) -> 0 | I22: =ROUND(MAX(0,I21*(1+I$8)-AE22),2) -> 0 | ... K22: =ROUND(MAX(0,K21*(1+K$8)-AG22),2) -> 0 | L22: =SUM(B22:K22) -> 13941.55 | M22: =SUMPRODUCT(B21:K21,$B$8:$K$8) -> 171.56619 | N22: =MIN(B21*(1+B$8),B$9) -> 0 | O22: =MIN(C21*(1+C$8),C$9) -> 50 | P22: =MIN(D21*(1+D$8),D$9) -> 75 | Q22: =MIN(E21*(1+E$8),E$9) -> 95 | R22: =MIN(F21*(1+F$8),F$9) -> 310 | S22: =MIN(G21*(1+G$8),G$9) -> 0 | T22: =MIN(H21*(1+H$8),H$9) -> 0 | U22: =MIN(I21*(1+I$8),I$9) -> 0 | ... W22: =MIN(K21*(1+K$8),K$9) -> 0 | X22: =MIN(B21*(1+B$8),MAX(N22,$B$11-SUM(O22:W22))) -> 0 | Y22: =MIN(C21*(1+C$8),MAX(O22,$B$11-SUM(X22:X22)-SUM(P22:W22))) -> 230.42 | Z22: =MIN(D21*(1+D$8),MAX(P22,$B$11-SUM(X22:Y22)-SUM(Q22:W22))) -> 79.58 | AA22: =MIN(E21*(1+E$8),MAX(Q22,$B$11-SUM(X22:Z22)-SUM(R22:W22))) -> 95 | AB22: =MIN(F21*(1+F$8),MAX(R22,$B$11-SUM(X22:AA22)-SUM(S22:W22))) -> 310 | AC22: =MIN(G21*(1+G$8),MAX(S22,$B$11-SUM(X22:AB22)-SUM(T22:W22))) -> 0 | AD22: =MIN(H21*(1+H$8),MAX(T22,$B$11-SUM(X22:AC22)-SUM(U22:W22))) -> 0 | AE22: =MIN(I21*(1+I$8),MAX(U22,$B$11-SUM(X22:AD22)-SUM(V22:W22))) -> 0 | AF22: =MIN(J21*(1+J$8),MAX(V22,$B$11-SUM(X22:AE22)-SUM(W22:W22))) -> 0 | AG22: =MIN(K21*(1+K$8),MAX(W22,$B$11-SUM(X22:AF22))) -> 0 | AI22: =ROUND(MAX(0,AI21*(1+B$8)-BE22),2) -> 465.3 | AJ22: =ROUND(MAX(0,AJ21*(1+C$8)-BF22),2) -> 800 | AK22: =ROUND(MAX(0,AK21*(1+D$8)-BG22),2) -> 2707.5 | AL22: =ROUND(MAX(0,AL21*(1+E$8)-BH22),2) -> 3927.91 | AM22: =ROUND(MAX(0,AM21*(1+F$8)-BI22),2) -> 7310.72 | AN22: =ROUND(MAX(0,AN21*(1+G$8)-BJ22),2) -> 0 | AO22: =ROUND(MAX(0,AO21*(1+H$8)-BK22),2) -> 0 | AP22: =ROUND(MAX(0,AP21*(1+I$8)-BL22),2) -> 0 | ... AR22: =ROUND(MAX(0,AR21*(1+K$8)-BN22),2) -> 0 | AS22: =SUM(AI22:AR22) -> 15211.43 | AT22: =SUMPRODUCT(AI21:AR21,$B$8:$K$8) -> 182.93382 | AU22: =MIN(AI21*(1+B$8),B$9) -> 35 | AV22: =MIN(AJ21*(1+C$8),C$9) -> 50 | AW22: =MIN(AK21*(1+D$8),D$9) -> 75 | AX22: =MIN(AL21*(1+E$8),E$9) -> 95 | AY22: =MIN(AM21*(1+F$8),F$9) -> 310 | AZ22: =MIN(AN21*(1+G$8),G$9) -> 0 | BA22: =MIN(AO21*(1+H$8),H$9) -> 0 | BB22: =MIN(AP21*(1+I$8),I$9) -> 0 | ... BD22: =MIN(AR21*(1+K$8),K$9) -> 0 | BE22: =MIN(AI21*(1+B$8),MAX(AU22,$B$12-SUM(AV22:BD22))) -> 35 | BF22: =MIN(AJ21*(1+C$8),MAX(AV22,$B$12-SUM(BE22:BE22)-SUM(AW22:BD22))) -> 50 | BG22: =MIN(AK21*(1+D$8),MAX(AW22,$B$12-SUM(BE22:BF22)-SUM(AX22:BD22))) -> 75 | BH22: =MIN(AL21*(1+E$8),MAX(AX22,$B$12-SUM(BE22:BG22)-SUM(AY22:BD22))) -> 95 | BI22: =MIN(AM21*(1+F$8),MAX(AY22,$B$12-SUM(BE22:BH22)-SUM(AZ22:BD22))) -> 310 | BJ22: =MIN(AN21*(1+G$8),MAX(AZ22,$B$12-SUM(BE22:BI22)-SUM(BA22:BD22))) -> 0 | BK22: =MIN(AO21*(1+H$8),MAX(BA22,$B$12-SUM(BE22:BJ22)-SUM(BB22:BD22))) -> 0 | BL22: =MIN(AP21*(1+I$8),MAX(BB22,$B$12-SUM(BE22:BK22)-SUM(BC22:BD22))) -> 0 | BM22: =MIN(AQ21*(1+J$8),MAX(BC22,$B$12-SUM(BE22:BL22)-SUM(BD22:BD22))) -> 0 | BN22: =MIN(AR21*(1+K$8),MAX(BD22,$B$12-SUM(BE22:BM22))) -> 0
A23: 9 | B23: =ROUND(MAX(0,B22*(1+B$8)-X23),2) -> 0 | C23: =ROUND(MAX(0,C22*(1+C$8)-Y23),2) -> 0 | D23: =ROUND(MAX(0,D22*(1+D$8)-Z23),2) -> 2448.33 | E23: =ROUND(MAX(0,E22*(1+E$8)-AA23),2) -> 3904.59 | F23: =ROUND(MAX(0,F22*(1+F$8)-AB23),2) -> 7042.76 | G23: =ROUND(MAX(0,G22*(1+G$8)-AC23),2) -> 0 | H23: =ROUND(MAX(0,H22*(1+H$8)-AD23),2) -> 0 | I23: =ROUND(MAX(0,I22*(1+I$8)-AE23),2) -> 0 | ... K23: =ROUND(MAX(0,K22*(1+K$8)-AG23),2) -> 0 | L23: =SUM(B23:K23) -> 13395.68 | M23: =SUMPRODUCT(B22:K22,$B$8:$K$8) -> 169.13086 | N23: =MIN(B22*(1+B$8),B$9) -> 0 | O23: =MIN(C22*(1+C$8),C$9) -> 0 | P23: =MIN(D22*(1+D$8),D$9) -> 75 | Q23: =MIN(E22*(1+E$8),E$9) -> 95 | R23: =MIN(F22*(1+F$8),F$9) -> 310 | S23: =MIN(G22*(1+G$8),G$9) -> 0 | T23: =MIN(H22*(1+H$8),H$9) -> 0 | U23: =MIN(I22*(1+I$8),I$9) -> 0 | ... W23: =MIN(K22*(1+K$8),K$9) -> 0 | X23: =MIN(B22*(1+B$8),MAX(N23,$B$11-SUM(O23:W23))) -> 0 | Y23: =MIN(C22*(1+C$8),MAX(O23,$B$11-SUM(X23:X23)-SUM(P23:W23))) -> 0 | Z23: =MIN(D22*(1+D$8),MAX(P23,$B$11-SUM(X23:Y23)-SUM(Q23:W23))) -> 310 | AA23: =MIN(E22*(1+E$8),MAX(Q23,$B$11-SUM(X23:Z23)-SUM(R23:W23))) -> 95 | AB23: =MIN(F22*(1+F$8),MAX(R23,$B$11-SUM(X23:AA23)-SUM(S23:W23))) -> 310 | AC23: =MIN(G22*(1+G$8),MAX(S23,$B$11-SUM(X23:AB23)-SUM(T23:W23))) -> 0 | AD23: =MIN(H22*(1+H$8),MAX(T23,$B$11-SUM(X23:AC23)-SUM(U23:W23))) -> 0 | AE23: =MIN(I22*(1+I$8),MAX(U23,$B$11-SUM(X23:AD23)-SUM(V23:W23))) -> 0 | AF23: =MIN(J22*(1+J$8),MAX(V23,$B$11-SUM(X23:AE23)-SUM(W23:W23))) -> 0 | AG23: =MIN(K22*(1+K$8),MAX(W23,$B$11-SUM(X23:AF23))) -> 0 | AI23: =ROUND(MAX(0,AI22*(1+B$8)-BE23),2) -> 441.12 | AJ23: =ROUND(MAX(0,AJ22*(1+C$8)-BF23),2) -> 750 | AK23: =ROUND(MAX(0,AK22*(1+D$8)-BG23),2) -> 2688 | AL23: =ROUND(MAX(0,AL22*(1+E$8)-BH23),2) -> 3904.59 | AM23: =ROUND(MAX(0,AM22*(1+F$8)-BI23),2) -> 7042.76 | AN23: =ROUND(MAX(0,AN22*(1+G$8)-BJ23),2) -> 0 | AO23: =ROUND(MAX(0,AO22*(1+H$8)-BK23),2) -> 0 | AP23: =ROUND(MAX(0,AP22*(1+I$8)-BL23),2) -> 0 | ... AR23: =ROUND(MAX(0,AR22*(1+K$8)-BN23),2) -> 0 | AS23: =SUM(AI23:AR23) -> 14826.47 | AT23: =SUMPRODUCT(AI22:AR22,$B$8:$K$8) -> 180.04297 | AU23: =MIN(AI22*(1+B$8),B$9) -> 35 | AV23: =MIN(AJ22*(1+C$8),C$9) -> 50 | AW23: =MIN(AK22*(1+D$8),D$9) -> 75 | AX23: =MIN(AL22*(1+E$8),E$9) -> 95 | AY23: =MIN(AM22*(1+F$8),F$9) -> 310 | AZ23: =MIN(AN22*(1+G$8),G$9) -> 0 | BA23: =MIN(AO22*(1+H$8),H$9) -> 0 | BB23: =MIN(AP22*(1+I$8),I$9) -> 0 | ... BD23: =MIN(AR22*(1+K$8),K$9) -> 0 | BE23: =MIN(AI22*(1+B$8),MAX(AU23,$B$12-SUM(AV23:BD23))) -> 35 | BF23: =MIN(AJ22*(1+C$8),MAX(AV23,$B$12-SUM(BE23:BE23)-SUM(AW23:BD23))) -> 50 | BG23: =MIN(AK22*(1+D$8),MAX(AW23,$B$12-SUM(BE23:BF23)-SUM(AX23:BD23))) -> 75 | BH23: =MIN(AL22*(1+E$8),MAX(AX23,$B$12-SUM(BE23:BG23)-SUM(AY23:BD23))) -> 95 | BI23: =MIN(AM22*(1+F$8),MAX(AY23,$B$12-SUM(BE23:BH23)-SUM(AZ23:BD23))) -> 310 | BJ23: =MIN(AN22*(1+G$8),MAX(AZ23,$B$12-SUM(BE23:BI23)-SUM(BA23:BD23))) -> 0 | BK23: =MIN(AO22*(1+H$8),MAX(BA23,$B$12-SUM(BE23:BJ23)-SUM(BB23:BD23))) -> 0 | BL23: =MIN(AP22*(1+I$8),MAX(BB23,$B$12-SUM(BE23:BK23)-SUM(BC23:BD23))) -> 0 | BM23: =MIN(AQ22*(1+J$8),MAX(BC23,$B$12-SUM(BE23:BL23)-SUM(BD23:BD23))) -> 0 | BN23: =MIN(AR22*(1+K$8),MAX(BD23,$B$12-SUM(BE23:BM23))) -> 0
A24: 10 | B24: =ROUND(MAX(0,B23*(1+B$8)-X24),2) -> 0 | C24: =ROUND(MAX(0,C23*(1+C$8)-Y24),2) -> 0 | D24: =ROUND(MAX(0,D23*(1+D$8)-Z24),2) -> 2188.52 | E24: =ROUND(MAX(0,E23*(1+E$8)-AA24),2) -> 3880.85 | F24: =ROUND(MAX(0,F23*(1+F$8)-AB24),2) -> 6773.26 | G24: =ROUND(MAX(0,G23*(1+G$8)-AC24),2) -> 0 | H24: =ROUND(MAX(0,H23*(1+H$8)-AD24),2) -> 0 | I24: =ROUND(MAX(0,I23*(1+I$8)-AE24),2) -> 0 | ... K24: =ROUND(MAX(0,K23*(1+K$8)-AG24),2) -> 0 | L24: =SUM(B24:K24) -> 12842.63 | M24: =SUMPRODUCT(B23:K23,$B$8:$K$8) -> 161.9454 | N24: =MIN(B23*(1+B$8),B$9) -> 0 | O24: =MIN(C23*(1+C$8),C$9) -> 0 | P24: =MIN(D23*(1+D$8),D$9) -> 75 | Q24: =MIN(E23*(1+E$8),E$9) -> 95 | R24: =MIN(F23*(1+F$8),F$9) -> 310 | S24: =MIN(G23*(1+G$8),G$9) -> 0 | T24: =MIN(H23*(1+H$8),H$9) -> 0 | U24: =MIN(I23*(1+I$8),I$9) -> 0 | ... W24: =MIN(K23*(1+K$8),K$9) -> 0 | X24: =MIN(B23*(1+B$8),MAX(N24,$B$11-SUM(O24:W24))) -> 0 | Y24: =MIN(C23*(1+C$8),MAX(O24,$B$11-SUM(X24:X24)-SUM(P24:W24))) -> 0 | Z24: =MIN(D23*(1+D$8),MAX(P24,$B$11-SUM(X24:Y24)-SUM(Q24:W24))) -> 310 | AA24: =MIN(E23*(1+E$8),MAX(Q24,$B$11-SUM(X24:Z24)-SUM(R24:W24))) -> 95 | AB24: =MIN(F23*(1+F$8),MAX(R24,$B$11-SUM(X24:AA24)-SUM(S24:W24))) -> 310 | AC24: =MIN(G23*(1+G$8),MAX(S24,$B$11-SUM(X24:AB24)-SUM(T24:W24))) -> 0 | AD24: =MIN(H23*(1+H$8),MAX(T24,$B$11-SUM(X24:AC24)-SUM(U24:W24))) -> 0 | AE24: =MIN(I23*(1+I$8),MAX(U24,$B$11-SUM(X24:AD24)-SUM(V24:W24))) -> 0 | AF24: =MIN(J23*(1+J$8),MAX(V24,$B$11-SUM(X24:AE24)-SUM(W24:W24))) -> 0 | AG24: =MIN(K23*(1+K$8),MAX(W24,$B$11-SUM(X24:AF24))) -> 0 | AI24: =ROUND(MAX(0,AI23*(1+B$8)-BE24),2) -> 416.38 | AJ24: =ROUND(MAX(0,AJ23*(1+C$8)-BF24),2) -> 700 | AK24: =ROUND(MAX(0,AK23*(1+D$8)-BG24),2) -> 2668.1 | AL24: =ROUND(MAX(0,AL23*(1+E$8)-BH24),2) -> 3880.85 | AM24: =ROUND(MAX(0,AM23*(1+F$8)-BI24),2) -> 6773.26 | AN24: =ROUND(MAX(0,AN23*(1+G$8)-BJ24),2) -> 0 | AO24: =ROUND(MAX(0,AO23*(1+H$8)-BK24),2) -> 0 | AP24: =ROUND(MAX(0,AP23*(1+I$8)-BL24),2) -> 0 | ... AR24: =ROUND(MAX(0,AR23*(1+K$8)-BN24),2) -> 0 | AS24: =SUM(AI24:AR24) -> 14438.59 | AT24: =SUMPRODUCT(AI23:AR23,$B$8:$K$8) -> 177.11468 | AU24: =MIN(AI23*(1+B$8),B$9) -> 35 | AV24: =MIN(AJ23*(1+C$8),C$9) -> 50 | AW24: =MIN(AK23*(1+D$8),D$9) -> 75 | AX24: =MIN(AL23*(1+E$8),E$9) -> 95 | AY24: =MIN(AM23*(1+F$8),F$9) -> 310 | AZ24: =MIN(AN23*(1+G$8),G$9) -> 0 | BA24: =MIN(AO23*(1+H$8),H$9) -> 0 | BB24: =MIN(AP23*(1+I$8),I$9) -> 0 | ... BD24: =MIN(AR23*(1+K$8),K$9) -> 0 | BE24: =MIN(AI23*(1+B$8),MAX(AU24,$B$12-SUM(AV24:BD24))) -> 35 | BF24: =MIN(AJ23*(1+C$8),MAX(AV24,$B$12-SUM(BE24:BE24)-SUM(AW24:BD24))) -> 50 | BG24: =MIN(AK23*(1+D$8),MAX(AW24,$B$12-SUM(BE24:BF24)-SUM(AX24:BD24))) -> 75 | BH24: =MIN(AL23*(1+E$8),MAX(AX24,$B$12-SUM(BE24:BG24)-SUM(AY24:BD24))) -> 95 | BI24: =MIN(AM23*(1+F$8),MAX(AY24,$B$12-SUM(BE24:BH24)-SUM(AZ24:BD24))) -> 310 | BJ24: =MIN(AN23*(1+G$8),MAX(AZ24,$B$12-SUM(BE24:BI24)-SUM(BA24:BD24))) -> 0 | BK24: =MIN(AO23*(1+H$8),MAX(BA24,$B$12-SUM(BE24:BJ24)-SUM(BB24:BD24))) -> 0 | BL24: =MIN(AP23*(1+I$8),MAX(BB24,$B$12-SUM(BE24:BK24)-SUM(BC24:BD24))) -> 0 | BM24: =MIN(AQ23*(1+J$8),MAX(BC24,$B$12-SUM(BE24:BL24)-SUM(BD24:BD24))) -> 0 | BN24: =MIN(AR23*(1+K$8),MAX(BD24,$B$12-SUM(BE24:BM24))) -> 0
A25: 11 | B25: =ROUND(MAX(0,B24*(1+B$8)-X25),2) -> 0 | C25: =ROUND(MAX(0,C24*(1+C$8)-Y25),2) -> 0 | D25: =ROUND(MAX(0,D24*(1+D$8)-Z25),2) -> 1923.38 | E25: =ROUND(MAX(0,E24*(1+E$8)-AA25),2) -> 3856.68 | F25: =ROUND(MAX(0,F24*(1+F$8)-AB25),2) -> 6502.21 | G25: =ROUND(MAX(0,G24*(1+G$8)-AC25),2) -> 0 | H25: =ROUND(MAX(0,H24*(1+H$8)-AD25),2) -> 0 | I25: =ROUND(MAX(0,I24*(1+I$8)-AE25),2) -> 0 | ... K25: =ROUND(MAX(0,K24*(1+K$8)-AG25),2) -> 0 | L25: =SUM(B25:K25) -> 12282.27 | M25: =SUMPRODUCT(B24:K24,$B$8:$K$8) -> 154.63642 | N25: =MIN(B24*(1+B$8),B$9) -> 0 | O25: =MIN(C24*(1+C$8),C$9) -> 0 | P25: =MIN(D24*(1+D$8),D$9) -> 75 | Q25: =MIN(E24*(1+E$8),E$9) -> 95 | R25: =MIN(F24*(1+F$8),F$9) -> 310 | S25: =MIN(G24*(1+G$8),G$9) -> 0 | T25: =MIN(H24*(1+H$8),H$9) -> 0 | U25: =MIN(I24*(1+I$8),I$9) -> 0 | ... W25: =MIN(K24*(1+K$8),K$9) -> 0 | X25: =MIN(B24*(1+B$8),MAX(N25,$B$11-SUM(O25:W25))) -> 0 | Y25: =MIN(C24*(1+C$8),MAX(O25,$B$11-SUM(X25:X25)-SUM(P25:W25))) -> 0 | Z25: =MIN(D24*(1+D$8),MAX(P25,$B$11-SUM(X25:Y25)-SUM(Q25:W25))) -> 310 | AA25: =MIN(E24*(1+E$8),MAX(Q25,$B$11-SUM(X25:Z25)-SUM(R25:W25))) -> 95 | AB25: =MIN(F24*(1+F$8),MAX(R25,$B$11-SUM(X25:AA25)-SUM(S25:W25))) -> 310 | AC25: =MIN(G24*(1+G$8),MAX(S25,$B$11-SUM(X25:AB25)-SUM(T25:W25))) -> 0 | AD25: =MIN(H24*(1+H$8),MAX(T25,$B$11-SUM(X25:AC25)-SUM(U25:W25))) -> 0 | AE25: =MIN(I24*(1+I$8),MAX(U25,$B$11-SUM(X25:AD25)-SUM(V25:W25))) -> 0 | AF25: =MIN(J24*(1+J$8),MAX(V25,$B$11-SUM(X25:AE25)-SUM(W25:W25))) -> 0 | AG25: =MIN(K24*(1+K$8),MAX(W25,$B$11-SUM(X25:AF25))) -> 0 | AI25: =ROUND(MAX(0,AI24*(1+B$8)-BE25),2) -> 391.06 | AJ25: =ROUND(MAX(0,AJ24*(1+C$8)-BF25),2) -> 650 | AK25: =ROUND(MAX(0,AK24*(1+D$8)-BG25),2) -> 2647.8 | AL25: =ROUND(MAX(0,AL24*(1+E$8)-BH25),2) -> 3856.68 | AM25: =ROUND(MAX(0,AM24*(1+F$8)-BI25),2) -> 6502.21 | AN25: =ROUND(MAX(0,AN24*(1+G$8)-BJ25),2) -> 0 | AO25: =ROUND(MAX(0,AO24*(1+H$8)-BK25),2) -> 0 | AP25: =ROUND(MAX(0,AP24*(1+I$8)-BL25),2) -> 0 | ... AR25: =ROUND(MAX(0,AR24*(1+K$8)-BN25),2) -> 0 | AS25: =SUM(AI25:AR25) -> 14047.75 | AT25: =SUMPRODUCT(AI24:AR24,$B$8:$K$8) -> 174.14864 | AU25: =MIN(AI24*(1+B$8),B$9) -> 35 | AV25: =MIN(AJ24*(1+C$8),C$9) -> 50 | AW25: =MIN(AK24*(1+D$8),D$9) -> 75 | AX25: =MIN(AL24*(1+E$8),E$9) -> 95 | AY25: =MIN(AM24*(1+F$8),F$9) -> 310 | AZ25: =MIN(AN24*(1+G$8),G$9) -> 0 | BA25: =MIN(AO24*(1+H$8),H$9) -> 0 | BB25: =MIN(AP24*(1+I$8),I$9) -> 0 | ... BD25: =MIN(AR24*(1+K$8),K$9) -> 0 | BE25: =MIN(AI24*(1+B$8),MAX(AU25,$B$12-SUM(AV25:BD25))) -> 35 | BF25: =MIN(AJ24*(1+C$8),MAX(AV25,$B$12-SUM(BE25:BE25)-SUM(AW25:BD25))) -> 50 | BG25: =MIN(AK24*(1+D$8),MAX(AW25,$B$12-SUM(BE25:BF25)-SUM(AX25:BD25))) -> 75 | BH25: =MIN(AL24*(1+E$8),MAX(AX25,$B$12-SUM(BE25:BG25)-SUM(AY25:BD25))) -> 95 | BI25: =MIN(AM24*(1+F$8),MAX(AY25,$B$12-SUM(BE25:BH25)-SUM(AZ25:BD25))) -> 310 | BJ25: =MIN(AN24*(1+G$8),MAX(AZ25,$B$12-SUM(BE25:BI25)-SUM(BA25:BD25))) -> 0 | BK25: =MIN(AO24*(1+H$8),MAX(BA25,$B$12-SUM(BE25:BJ25)-SUM(BB25:BD25))) -> 0 | BL25: =MIN(AP24*(1+I$8),MAX(BB25,$B$12-SUM(BE25:BK25)-SUM(BC25:BD25))) -> 0 | BM25: =MIN(AQ24*(1+J$8),MAX(BC25,$B$12-SUM(BE25:BL25)-SUM(BD25:BD25))) -> 0 | BN25: =MIN(AR24*(1+K$8),MAX(BD25,$B$12-SUM(BE25:BM25))) -> 0
