Workbook

Sheet START HERE
B2: SMALL BUSINESS BOOKKEEPING & INVOICE TRACKER
B5: Welcome! One workbook runs the money side of a solo service business: what comes in, what goes
B6: out, who still owes you, and roughly what to set aside for taxes.
B8: HOW TO USE (3 steps)
B9: 1. 'Income & Expense Ledger' tab: log every payment in and every business expense out — date, type,
B10: category, amount in the yellow cells. Monthly subtotals and the P&L fill themselves.
B11: 2. 'Invoice Tracker' tab: one row per invoice with sent / due / paid dates. The sheet stamps each one
B12: PAID, SENT, or OVERDUE, shows days overdue, and totals what's still owed to you.
B13: 3. Once a month, glance at 'P&L Dashboard'. Once a quarter, open 'Quarterly Tax Estimate' and move
B14: the suggested set-aside into savings. Log business drives in 'Mileage Log' as you go.
B16: THE WORKED EXAMPLE — WALK THROUGH IT
B17: The numbers already in the sheets are one realistic example business (a part-time solo cleaner):
... B41: Questions or a formula acting up? Message us on Etsy any time — we answer fast and we'll fix it.

Sheet Income & Expense Ledger
B2: INCOME & EXPENSE LEDGER
B4: Money in (year so far) | C4: =SUMIF($C$10:$C$209,"Income",$F$10:$F$209) -> 4650
B5: Money out (year so far) | C5: =SUMIF($C$10:$C$209,"Expense",$F$10:$F$209) -> 725.46
B6: Net profit (year so far) | C6: =C4-C5 -> 3924.54
B8: Log one row per transaction. Type must be exactly Income or Expense — the totals count those words. 'Mo.' fills itself from the date.
B9: Date | C9: Type | D9: Category | E9: Description / client | F9: Amount | G9: Mo. | I9: Month | J9: Money in | K9: Money out | L9: Net
B10: 46028 | C10: Income | D10: Client payment | E10: INV-1001 — Harbor Dental, weekly office cleaning (Jan) | F10: 480 | G10: =IF($B10="","",MONTH($B10)) -> 1 | I10: Jan | J10: =SUMIFS($F$10:$F$209,$G$10:$G$209,1,$C$10:$C$209,"Income") -> 1500 | K10: =SUMIFS($F$10:$F$209,$G$10:$G$209,1,$C$10:$C$209,"Expense") -> 205.63 | L10: =IF(AND(J10=0,K10=0),"",J10-K10) -> 1294.37
B11: 46031 | C11: Income | D11: Client payment | E11: INV-1002 — Reyes family, one-time deep clean | F11: 260 | G11: =IF($B11="","",MONTH($B11)) -> 1 | I11: Feb | J11: =SUMIFS($F$10:$F$209,$G$10:$G$209,2,$C$10:$C$209,"Income") -> 1520 | K11: =SUMIFS($F$10:$F$209,$G$10:$G$209,2,$C$10:$C$209,"Expense") -> 238.24 | L11: =IF(AND(J11=0,K11=0),"",J11-K11) -> 1281.76
B12: 46034 | C12: Expense | D12: Supplies | E12: Cleaning supplies restock | F12: 84.63 | G12: =IF($B12="","",MONTH($B12)) -> 1 | I12: Mar | J12: =SUMIFS($F$10:$F$209,$G$10:$G$209,3,$C$10:$C$209,"Income") -> 1630 | K12: =SUMIFS($F$10:$F$209,$G$10:$G$209,3,$C$10:$C$209,"Expense") -> 220.59 | L12: =IF(AND(J12=0,K12=0),"",J12-K12) -> 1409.41
B13: 46037 | C13: Expense | D13: Insurance | E13: Liability insurance (monthly) | F13: 42 | G13: =IF($B13="","",MONTH($B13)) -> 1 | I13: Apr | J13: =SUMIFS($F$10:$F$209,$G$10:$G$209,4,$C$10:$C$209,"Income") -> 0 | K13: =SUMIFS($F$10:$F$209,$G$10:$G$209,4,$C$10:$C$209,"Expense") -> 61 | L13: =IF(AND(J13=0,K13=0),"",J13-K13) -> -61
B14: 46042 | C14: Income | D14: Client payment | E14: INV-1003 — Birchwood Apartments, move-out cleans x2 | F14: 520 | G14: =IF($B14="","",MONTH($B14)) -> 1 | I14: May | J14: =SUMIFS($F$10:$F$209,$G$10:$G$209,5,$C$10:$C$209,"Income") -> 0 | K14: =SUMIFS($F$10:$F$209,$G$10:$G$209,5,$C$10:$C$209,"Expense") -> 0 | L14: =IF(AND(J14=0,K14=0),"",J14-K14)
B15: 46044 | C15: Expense | D15: Advertising | E15: Neighborhood flyers + local ad | F15: 60 | G15: =IF($B15="","",MONTH($B15)) -> 1 | I15: Jun | J15: =SUMIFS($F$10:$F$209,$G$10:$G$209,6,$C$10:$C$209,"Income") -> 0 | K15: =SUMIFS($F$10:$F$209,$G$10:$G$209,6,$C$10:$C$209,"Expense") -> 0 | L15: =IF(AND(J15=0,K15=0),"",J15-K15)
B16: 46050 | C16: Expense | D16: Software / subscriptions | E16: Scheduling app (monthly) | F16: 19 | G16: =IF($B16="","",MONTH($B16)) -> 1 | I16: Jul | J16: =SUMIFS($F$10:$F$209,$G$10:$G$209,7,$C$10:$C$209,"Income") -> 0 | K16: =SUMIFS($F$10:$F$209,$G$10:$G$209,7,$C$10:$C$209,"Expense") -> 0 | L16: =IF(AND(J16=0,K16=0),"",J16-K16)
B17: 46052 | C17: Income | D17: Client payment | E17: INV-1004 — Harbor Dental, carpet + window add-on | F17: 240 | G17: =IF($B17="","",MONTH($B17)) -> 1 | I17: Aug | J17: =SUMIFS($F$10:$F$209,$G$10:$G$209,8,$C$10:$C$209,"Income") -> 0 | K17: =SUMIFS($F$10:$F$209,$G$10:$G$209,8,$C$10:$C$209,"Expense") -> 0 | L17: =IF(AND(J17=0,K17=0),"",J17-K17)
B18: 46056 | C18: Income | D18: Client payment | E18: INV-1005 — Harbor Dental, weekly office cleaning (Feb) | F18: 480 | G18: =IF($B18="","",MONTH($B18)) -> 2 | I18: Sep | J18: =SUMIFS($F$10:$F$209,$G$10:$G$209,9,$C$10:$C$209,"Income") -> 0 | K18: =SUMIFS($F$10:$F$209,$G$10:$G$209,9,$C$10:$C$209,"Expense") -> 0 | L18: =IF(AND(J18=0,K18=0),"",J18-K18)
B19: 46059 | C19: Expense | D19: Supplies | E19: Vacuum bags + microfiber restock | F19: 47.25 | G19: =IF($B19="","",MONTH($B19)) -> 2 | I19: Oct | J19: =SUMIFS($F$10:$F$209,$G$10:$G$209,10,$C$10:$C$209,"Income") -> 0 | K19: =SUMIFS($F$10:$F$209,$G$10:$G$209,10,$C$10:$C$209,"Expense") -> 0 | L19: =IF(AND(J19=0,K19=0),"",J19-K19)
B20: 46063 | C20: Income | D20: Client payment | E20: INV-1006 — Nguyen rental, turnover cleans x4 | F20: 640 | G20: =IF($B20="","",MONTH($B20)) -> 2 | I20: Nov | J20: =SUMIFS($F$10:$F$209,$G$10:$G$209,11,$C$10:$C$209,"Income") -> 0 | K20: =SUMIFS($F$10:$F$209,$G$10:$G$209,11,$C$10:$C$209,"Expense") -> 0 | L20: =IF(AND(J20=0,K20=0),"",J20-K20)
B21: 46067 | C21: Expense | D21: Insurance | E21: Liability insurance (monthly) | F21: 42 | G21: =IF($B21="","",MONTH($B21)) -> 2 | I21: Dec | J21: =SUMIFS($F$10:$F$209,$G$10:$G$209,12,$C$10:$C$209,"Income") -> 0 | K21: =SUMIFS($F$10:$F$209,$G$10:$G$209,12,$C$10:$C$209,"Expense") -> 0 | L21: =IF(AND(J21=0,K21=0),"",J21-K21)
B22: 46071 | C22: Income | D22: Client payment | E22: INV-1007 — Reyes family, standard clean | F22: 140 | G22: =IF($B22="","",MONTH($B22)) -> 2 | I22: Year | J22: =SUM(J10:J21) -> 4650 | K22: =SUM(K10:K21) -> 725.46 | L22: =J22-K22 -> 3924.54
B23: 46077 | C23: Expense | D23: Equipment | E23: Replacement mop system | F23: 129.99 | G23: =IF($B23="","",MONTH($B23)) -> 2
B24: 46079 | C24: Expense | D24: Software / subscriptions | E24: Scheduling app (monthly) | F24: 19 | G24: =IF($B24="","",MONTH($B24)) -> 2
B25: 46080 | C25: Income | D25: Client payment | E25: INV-1008 — Birchwood Apartments, move-out clean | F25: 260 | G25: =IF($B25="","",MONTH($B25)) -> 2
B26: 46083 | C26: Income | D26: Client payment | E26: INV-1009 — Harbor Dental, weekly office cleaning (Mar) | F26: 480 | G26: =IF($B26="","",MONTH($B26)) -> 3
B27: 46086 | C27: Expense | D27: Supplies | E27: Cleaning supplies restock | F27: 96.12 | G27: =IF($B27="","",MONTH($B27)) -> 3
B28: 46090 | C28: Income | D28: Client payment | E28: INV-1010 — Nguyen rental, turnover cleans x5 | F28: 800 | G28: =IF($B28="","",MONTH($B28)) -> 3
B29: 46094 | C29: Expense | D29: Insurance | E29: Liability insurance (monthly) | F29: 42 | G29: =IF($B29="","",MONTH($B29)) -> 3
B30: 46098 | C30: Expense | D30: Phone | E30: Business share of phone plan | F30: 35 | G30: =IF($B30="","",MONTH($B30)) -> 3
B31: 46101 | C31: Income | D31: Client payment | E31: INV-1011 — Ferris & Co., quarterly deep clean | F31: 350 | G31: =IF($B31="","",MONTH($B31)) -> 3
B32: 46106 | C32: Expense | D32: Software / subscriptions | E32: Scheduling app (monthly) | F32: 19 | G32: =IF($B32="","",MONTH($B32)) -> 3
B33: 46108 | C33: Expense | D33: Bank / card fees | E33: Card reader fees (Q1) | F33: 28.47 | G33: =IF($B33="","",MONTH($B33)) -> 3
B34: 46125 | C34: Expense | D34: Insurance | E34: Liability insurance (monthly) | F34: 42 | G34: =IF($B34="","",MONTH($B34)) -> 4
B35: 46139 | C35: Expense | D35: Software / subscriptions | E35: Scheduling app (monthly) | F35: 19 | G35: =IF($B35="","",MONTH($B35)) -> 4
G36: =IF($B36="","",MONTH($B36))
G37: =IF($B37="","",MONTH($B37))
G38: =IF($B38="","",MONTH($B38))
G39: =IF($B39="","",MONTH($B39))
G40: =IF($B40="","",MONTH($B40))
G41: =IF($B41="","",MONTH($B41))
G42: =IF($B42="","",MONTH($B42))
G43: =IF($B43="","",MONTH($B43))
...

Sheet Invoice Tracker
B2: INVOICE TRACKER
B4: Invoiced (all invoices) | E4: =SUM($E$11:$E$110) -> 5740 | G4: # paid | H4: =COUNTIF($I$11:$I$110,"PAID") -> 11
B5: Collected (paid) | E5: =SUMIF($I$11:$I$110,"PAID",$E$11:$E$110) -> 4650 | G5: # awaiting | H5: =COUNTIF($I$11:$I$110,"SENT") -> 1
B6: Outstanding (unpaid) | E6: =E4-E5 -> 1090 | G6: # overdue | H6: =COUNTIF($I$11:$I$110,"OVERDUE") -> 2
B7: Overdue right now | E7: =SUMIF($I$11:$I$110,"OVERDUE",$E$11:$E$110) -> 610
B9: One row per invoice — yellow cells only, dates as real dates. Status and Days overdue calculate themselves: PAID once a paid date exists, OVERDUE when unpaid past the due date.
B10: Invoice # | C10: Client | D10: What for | E10: Amount | F10: Date sent | G10: Due date | H10: Date paid | I10: Status | J10: Days overdue
B11: INV-1001 | C11: Harbor Dental | D11: Weekly office cleaning — January | E11: 480 | F11: 46024 | G11: 46038 | H11: 46028 | I11: =IF($B11="","",IF($H11<>"","PAID",IF($G11="","SENT",IF(TODAY()>$G11,"OVERDUE","SENT")))) -> PAID | J11: =IF($I11="OVERDUE",TODAY()-$G11,"")
B12: INV-1002 | C12: Reyes family | D12: One-time deep clean | E12: 260 | F12: 46027 | G12: 46041 | H12: 46031 | I12: =IF($B12="","",IF($H12<>"","PAID",IF($G12="","SENT",IF(TODAY()>$G12,"OVERDUE","SENT")))) -> PAID | J12: =IF($I12="OVERDUE",TODAY()-$G12,"")
B13: INV-1003 | C13: Birchwood Apartments | D13: Move-out cleans (2 units) | E13: 520 | F13: 46035 | G13: 46049 | H13: 46042 | I13: =IF($B13="","",IF($H13<>"","PAID",IF($G13="","SENT",IF(TODAY()>$G13,"OVERDUE","SENT")))) -> PAID | J13: =IF($I13="OVERDUE",TODAY()-$G13,"")
B14: INV-1004 | C14: Harbor Dental | D14: Carpet + window add-on | E14: 240 | F14: 46048 | G14: 46062 | H14: 46052 | I14: =IF($B14="","",IF($H14<>"","PAID",IF($G14="","SENT",IF(TODAY()>$G14,"OVERDUE","SENT")))) -> PAID | J14: =IF($I14="OVERDUE",TODAY()-$G14,"")
B15: INV-1005 | C15: Harbor Dental | D15: Weekly office cleaning — February | E15: 480 | F15: 46054 | G15: 46068 | H15: 46056 | I15: =IF($B15="","",IF($H15<>"","PAID",IF($G15="","SENT",IF(TODAY()>$G15,"OVERDUE","SENT")))) -> PAID | J15: =IF($I15="OVERDUE",TODAY()-$G15,"")
B16: INV-1006 | C16: Nguyen rental | D16: Turnover cleans (4 stays) | E16: 640 | F16: 46057 | G16: 46071 | H16: 46063 | I16: =IF($B16="","",IF($H16<>"","PAID",IF($G16="","SENT",IF(TODAY()>$G16,"OVERDUE","SENT")))) -> PAID | J16: =IF($I16="OVERDUE",TODAY()-$G16,"")
B17: INV-1007 | C17: Reyes family | D17: Standard clean | E17: 140 | F17: 46069 | G17: 46083 | H17: 46071 | I17: =IF($B17="","",IF($H17<>"","PAID",IF($G17="","SENT",IF(TODAY()>$G17,"OVERDUE","SENT")))) -> PAID | J17: =IF($I17="OVERDUE",TODAY()-$G17,"")
B18: INV-1008 | C18: Birchwood Apartments | D18: Move-out clean (1 unit) | E18: 260 | F18: 46076 | G18: 46090 | H18: 46080 | I18: =IF($B18="","",IF($H18<>"","PAID",IF($G18="","SENT",IF(TODAY()>$G18,"OVERDUE","SENT")))) -> PAID | J18: =IF($I18="OVERDUE",TODAY()-$G18,"")
B19: INV-1009 | C19: Harbor Dental | D19: Weekly office cleaning — March | E19: 480 | F19: 46082 | G19: 46096 | H19: 46083 | I19: =IF($B19="","",IF($H19<>"","PAID",IF($G19="","SENT",IF(TODAY()>$G19,"OVERDUE","SENT")))) -> PAID | J19: =IF($I19="OVERDUE",TODAY()-$G19,"")
B20: INV-1010 | C20: Nguyen rental | D20: Turnover cleans (5 stays) | E20: 800 | F20: 46087 | G20: 46101 | H20: 46090 | I20: =IF($B20="","",IF($H20<>"","PAID",IF($G20="","SENT",IF(TODAY()>$G20,"OVERDUE","SENT")))) -> PAID | J20: =IF($I20="OVERDUE",TODAY()-$G20,"")
B21: INV-1011 | C21: Ferris & Co. | D21: Quarterly deep clean | E21: 350 | F21: 46097 | G21: 46111 | H21: 46101 | I21: =IF($B21="","",IF($H21<>"","PAID",IF($G21="","SENT",IF(TODAY()>$G21,"OVERDUE","SENT")))) -> PAID | J21: =IF($I21="OVERDUE",TODAY()-$G21,"")
B22: INV-1012 | C22: Birchwood Apartments | D22: Move-out clean (1 unit) | E22: 260 | F22: 46111 | G22: 46126 | I22: =IF($B22="","",IF($H22<>"","PAID",IF($G22="","SENT",IF(TODAY()>$G22,"OVERDUE","SENT")))) -> OVERDUE | J22: =IF($I22="OVERDUE",TODAY()-$G22,"") -> 111
B23: INV-1013 | C23: Ferris & Co. | D23: Window + break-room add-on | E23: 350 | F23: 46203 | G23: 46218 | I23: =IF($B23="","",IF($H23<>"","PAID",IF($G23="","SENT",IF(TODAY()>$G23,"OVERDUE","SENT")))) -> OVERDUE | J23: =IF($I23="OVERDUE",TODAY()-$G23,"") -> 19
B24: INV-1014 | C24: Nguyen rental | D24: Turnover cleans (3 stays) | E24: 480 | F24: 46227 | G24: 46257 | I24: =IF($B24="","",IF($H24<>"","PAID",IF($G24="","SENT",IF(TODAY()>$G24,"OVERDUE","SENT")))) -> SENT | J24: =IF($I24="OVERDUE",TODAY()-$G24,"")
I25: =IF($B25="","",IF($H25<>"","PAID",IF($G25="","SENT",IF(TODAY()>$G25,"OVERDUE","SENT")))) | J25: =IF($I25="OVERDUE",TODAY()-$G25,"")
I26: =IF($B26="","",IF($H26<>"","PAID",IF($G26="","SENT",IF(TODAY()>$G26,"OVERDUE","SENT")))) | J26: =IF($I26="OVERDUE",TODAY()-$G26,"")
I27: =IF($B27="","",IF($H27<>"","PAID",IF($G27="","SENT",IF(TODAY()>$G27,"OVERDUE","SENT")))) | J27: =IF($I27="OVERDUE",TODAY()-$G27,"")
I28: =IF($B28="","",IF($H28<>"","PAID",IF($G28="","SENT",IF(TODAY()>$G28,"OVERDUE","SENT")))) | J28: =IF($I28="OVERDUE",TODAY()-$G28,"")
I29: =IF($B29="","",IF($H29<>"","PAID",IF($G29="","SENT",IF(TODAY()>$G29,"OVERDUE","SENT")))) | J29: =IF($I29="OVERDUE",TODAY()-$G29,"")
I30: =IF($B30="","",IF($H30<>"","PAID",IF($G30="","SENT",IF(TODAY()>$G30,"OVERDUE","SENT")))) | J30: =IF($I30="OVERDUE",TODAY()-$G30,"")
I31: =IF($B31="","",IF($H31<>"","PAID",IF($G31="","SENT",IF(TODAY()>$G31,"OVERDUE","SENT")))) | J31: =IF($I31="OVERDUE",TODAY()-$G31,"")
I32: =IF($B32="","",IF($H32<>"","PAID",IF($G32="","SENT",IF(TODAY()>$G32,"OVERDUE","SENT")))) | J32: =IF($I32="OVERDUE",TODAY()-$G32,"")
I33: =IF($B33="","",IF($H33<>"","PAID",IF($G33="","SENT",IF(TODAY()>$G33,"OVERDUE","SENT")))) | J33: =IF($I33="OVERDUE",TODAY()-$G33,"")
I34: =IF($B34="","",IF($H34<>"","PAID",IF($G34="","SENT",IF(TODAY()>$G34,"OVERDUE","SENT")))) | J34: =IF($I34="OVERDUE",TODAY()-$G34,"")
I35: =IF($B35="","",IF($H35<>"","PAID",IF($G35="","SENT",IF(TODAY()>$G35,"OVERDUE","SENT")))) | J35: =IF($I35="OVERDUE",TODAY()-$G35,"")
I36: =IF($B36="","",IF($H36<>"","PAID",IF($G36="","SENT",IF(TODAY()>$G36,"OVERDUE","SENT")))) | J36: =IF($I36="OVERDUE",TODAY()-$G36,"")
... I110: =IF($B110="","",IF($H110<>"","PAID",IF($G110="","SENT",IF(TODAY()>$G110,"OVERDUE","SENT")))) | J110: =IF($I110="OVERDUE",TODAY()-$G110,"")
B112: Tip: send the invoice, then set Due date (e.g. sent + 14 days). The totals above always show exactly who owes you money.

Sheet Quarterly Tax Estimate
B2: QUARTERLY TAX ESTIMATE
B4: ESTIMATE ONLY — NOT TAX ADVICE. A simplified math helper for setting money aside.
B5: Rates change and your situation is unique — confirm with a tax professional or irs.gov before filing anything.
B7: YOUR YEAR SO FAR (auto — from the other tabs)
B8: Money in (Ledger) | C8: ='Income & Expense Ledger'!C4 -> 4650
B9: Business expenses (Ledger) | C9: ='Income & Expense Ledger'!C5 -> 725.46
B10: Mileage deduction (Mileage Log) | C10: ='Mileage Log'!C6 -> 162.4
B11: Estimated profit (in − expenses − mileage) | C11: =C8-C9-C10 -> 3762.14
B13: ASSUMPTIONS (yellow — adjust to your situation)
B14: Share of profit subject to SE tax | C14: 0.9235
B15: Self-employment tax rate (Social Security + Medicare) | C15: 0.153
B16: Estimated income tax rate (your rough bracket) | C16: 0.12
B17: Defaults are the widely used federal self-employment figures plus a rough income-tax rate. Rates change — check irs.gov. State tax and the Social Security wage cap are NOT included.
B19: THE ESTIMATE (year so far)
B20: Profit subject to SE tax | C20: =MAX(0,$C$11)*$C$14 -> 3474.3363
B21: Estimated self-employment tax | C21: =$C$20*$C$15 -> 531.57345
B22: Estimated income tax (after half-SE deduction) | C22: =MAX(0,$C$11-$C$21/2)*$C$16 -> 419.56239
B23: Total estimated tax (year so far) | C23: =$C$21+$C$22 -> 951.13585
B24: Suggested set-aside (share of every dollar in) | C24: =IFERROR($C$23/$C$8,0) -> 0.20454534
B25: Effective rate on profit (used by the table below) | C25: =IF($C$11<=0,0,$C$23/$C$11) -> 0.25281777
B27: QUARTER BY QUARTER
B28: Quarter | C28: Profit | D28: Set aside
B29: Q1 (Jan–Mar) | C29: =SUMIFS('Income & Expense Ledger'!$F$10:$F$209,'Income & Expense Ledger'!$G$10:$G$209,">=1",'Income & Expense Ledger'!$G$10:$G$209,"<=3",'Income & Expense Ledger'!$C$10:$C$209,"Income")-SUMIFS('Income & Expense Ledger'!$F$10:$F$209,'Income & Expense Ledger'!$G$10:$G$209,">=1",'Income & Expense Ledger'!$G$10:$G$209,"<=3",'Income & Expense Ledger'!$C$10:$C$209,"Expense")-SUMIFS('Mileage Log'!$E$9:$E$208,'Mileage Log'!$F$9:$F$208,">=1",'Mileage Log'!$F$9:$F$208,"<=3") -> 3823.14 | D29: =MAX(0,$C29)*$C$25 -> 966.55773
B30: Q2 (Apr–Jun) | C30: =SUMIFS('Income & Expense Ledger'!$F$10:$F$209,'Income & Expense Ledger'!$G$10:$G$209,">=4",'Income & Expense Ledger'!$G$10:$G$209,"<=6",'Income & Expense Ledger'!$C$10:$C$209,"Income")-SUMIFS('Income & Expense Ledger'!$F$10:$F$209,'Income & Expense Ledger'!$G$10:$G$209,">=4",'Income & Expense Ledger'!$G$10:$G$209,"<=6",'Income & Expense Ledger'!$C$10:$C$209,"Expense")-SUMIFS('Mileage Log'!$E$9:$E$208,'Mileage Log'!$F$9:$F$208,">=4",'Mileage Log'!$F$9:$F$208,"<=6") -> -61 | D30: =MAX(0,$C30)*$C$25 -> 0
B31: Q3 (Jul–Sep) | C31: =SUMIFS('Income & Expense Ledger'!$F$10:$F$209,'Income & Expense Ledger'!$G$10:$G$209,">=7",'Income & Expense Ledger'!$G$10:$G$209,"<=9",'Income & Expense Ledger'!$C$10:$C$209,"Income")-SUMIFS('Income & Expense Ledger'!$F$10:$F$209,'Income & Expense Ledger'!$G$10:$G$209,">=7",'Income & Expense Ledger'!$G$10:$G$209,"<=9",'Income & Expense Ledger'!$C$10:$C$209,"Expense")-SUMIFS('Mileage Log'!$E$9:$E$208,'Mileage Log'!$F$9:$F$208,">=7",'Mileage Log'!$F$9:$F$208,"<=9") -> 0 | D31: =MAX(0,$C31)*$C$25 -> 0
B32: Q4 (Oct–Dec) | C32: =SUMIFS('Income & Expense Ledger'!$F$10:$F$209,'Income & Expense Ledger'!$G$10:$G$209,">=10",'Income & Expense Ledger'!$G$10:$G$209,"<=12",'Income & Expense Ledger'!$C$10:$C$209,"Income")-SUMIFS('Income & Expense Ledger'!$F$10:$F$209,'Income & Expense Ledger'!$G$10:$G$209,">=10",'Income & Expense Ledger'!$G$10:$G$209,"<=12",'Income & Expense Ledger'!$C$10:$C$209,"Expense")-SUMIFS('Mileage Log'!$E$9:$E$208,'Mileage Log'!$F$9:$F$208,">=10",'Mileage Log'!$F$9:$F$208,"<=12") -> 0 | D32: =MAX(0,$C32)*$C$25 -> 0
B33: Year | C33: =SUM(C29:C32) -> 3762.14 | D33: =SUM(D29:D32) -> 966.55773
B35: Actual estimated-tax due dates and safe-harbor rules live on IRS Form 1040-ES — this table just splits the year's estimate by when you earned it.
B36: Set-asides only count profitable quarters, so their total can run a little above the year estimate when a quarter lost money — better to over-save than under.
B38: Again: this whole tab is an estimate for setting money aside — not tax advice.

Sheet P&L Dashboard
B2: P&L DASHBOARD
B4: Nothing to type here — every number flows from the Ledger. Green months made money, red months lost it.
B6: Month | C6: Money in | D6: Money out | E6: Profit | F6: Margin
B7: Jan | C7: ='Income & Expense Ledger'!J10 -> 1500 | D7: ='Income & Expense Ledger'!K10 -> 205.63 | E7: =IF(AND(C7=0,D7=0),"",C7-D7) -> 1294.37 | F7: =IF(OR(C7=0,E7=""),"",E7/C7) -> 0.86291333
B8: Feb | C8: ='Income & Expense Ledger'!J11 -> 1520 | D8: ='Income & Expense Ledger'!K11 -> 238.24 | E8: =IF(AND(C8=0,D8=0),"",C8-D8) -> 1281.76 | F8: =IF(OR(C8=0,E8=""),"",E8/C8) -> 0.84326316
B9: Mar | C9: ='Income & Expense Ledger'!J12 -> 1630 | D9: ='Income & Expense Ledger'!K12 -> 220.59 | E9: =IF(AND(C9=0,D9=0),"",C9-D9) -> 1409.41 | F9: =IF(OR(C9=0,E9=""),"",E9/C9) -> 0.86466871
B10: Apr | C10: ='Income & Expense Ledger'!J13 -> 0 | D10: ='Income & Expense Ledger'!K13 -> 61 | E10: =IF(AND(C10=0,D10=0),"",C10-D10) -> -61 | F10: =IF(OR(C10=0,E10=""),"",E10/C10)
B11: May | C11: ='Income & Expense Ledger'!J14 -> 0 | D11: ='Income & Expense Ledger'!K14 -> 0 | E11: =IF(AND(C11=0,D11=0),"",C11-D11) | F11: =IF(OR(C11=0,E11=""),"",E11/C11)
B12: Jun | C12: ='Income & Expense Ledger'!J15 -> 0 | D12: ='Income & Expense Ledger'!K15 -> 0 | E12: =IF(AND(C12=0,D12=0),"",C12-D12) | F12: =IF(OR(C12=0,E12=""),"",E12/C12)
B13: Jul | C13: ='Income & Expense Ledger'!J16 -> 0 | D13: ='Income & Expense Ledger'!K16 -> 0 | E13: =IF(AND(C13=0,D13=0),"",C13-D13) | F13: =IF(OR(C13=0,E13=""),"",E13/C13)
B14: Aug | C14: ='Income & Expense Ledger'!J17 -> 0 | D14: ='Income & Expense Ledger'!K17 -> 0 | E14: =IF(AND(C14=0,D14=0),"",C14-D14) | F14: =IF(OR(C14=0,E14=""),"",E14/C14)
B15: Sep | C15: ='Income & Expense Ledger'!J18 -> 0 | D15: ='Income & Expense Ledger'!K18 -> 0 | E15: =IF(AND(C15=0,D15=0),"",C15-D15) | F15: =IF(OR(C15=0,E15=""),"",E15/C15)
B16: Oct | C16: ='Income & Expense Ledger'!J19 -> 0 | D16: ='Income & Expense Ledger'!K19 -> 0 | E16: =IF(AND(C16=0,D16=0),"",C16-D16) | F16: =IF(OR(C16=0,E16=""),"",E16/C16)
B17: Nov | C17: ='Income & Expense Ledger'!J20 -> 0 | D17: ='Income & Expense Ledger'!K20 -> 0 | E17: =IF(AND(C17=0,D17=0),"",C17-D17) | F17: =IF(OR(C17=0,E17=""),"",E17/C17)
B18: Dec | C18: ='Income & Expense Ledger'!J21 -> 0 | D18: ='Income & Expense Ledger'!K21 -> 0 | E18: =IF(AND(C18=0,D18=0),"",C18-D18) | F18: =IF(OR(C18=0,E18=""),"",E18/C18)
B19: Year | C19: =SUM(C7:C18) -> 4650 | D19: =SUM(D7:D18) -> 725.46 | E19: =C19-D19 -> 3924.54 | F19: =IF(C19=0,"",E19/C19) -> 0.8439871
B21: Best month (profit) | C21: =MAX(E7:E18) -> 1409.41
B22: Average month (months with income) | C22: =IFERROR(AVERAGEIF(C7:C18,">0",E7:E18),0) -> 1328.5133
B24: Profit here = money in − money out from the Ledger (a cash view). The mileage deduction is a tax-time figure — see the Quarterly Tax Estimate tab.

Sheet Mileage Log
B2: MILEAGE LOG
B4: Rate per mile: | C4: 0.7 | D4: ← enter the CURRENT standard mileage rate (check irs.gov — it changes most years)
B5: Total business miles | C5: =SUM($D$9:$D$208) -> 232
B6: Total mileage deduction | C6: =SUM($E$9:$E$208) -> 162.4
B8: Date | C8: Where / why (client, job) | D8: Miles | E8: Deduction | F8: Mo.
B9: 46028 | C9: Harbor Dental — weekly clean | D9: 18 | E9: =IF($D9="","",ROUND($D9*$C$4,2)) -> 12.6 | F9: =IF($B9="","",MONTH($B9)) -> 1
B10: 46031 | C10: Reyes family — deep clean | D10: 24 | E10: =IF($D10="","",ROUND($D10*$C$4,2)) -> 16.8 | F10: =IF($B10="","",MONTH($B10)) -> 1
B11: 46042 | C11: Birchwood Apartments — move-outs | D11: 31 | E11: =IF($D11="","",ROUND($D11*$C$4,2)) -> 21.7 | F11: =IF($B11="","",MONTH($B11)) -> 1
B12: 46056 | C12: Harbor Dental — weekly clean | D12: 18 | E12: =IF($D12="","",ROUND($D12*$C$4,2)) -> 12.6 | F12: =IF($B12="","",MONTH($B12)) -> 2
B13: 46063 | C13: Nguyen rental — turnovers | D13: 42 | E13: =IF($D13="","",ROUND($D13*$C$4,2)) -> 29.4 | F13: =IF($B13="","",MONTH($B13)) -> 2
B14: 46080 | C14: Birchwood Apartments — move-out | D14: 31 | E14: =IF($D14="","",ROUND($D14*$C$4,2)) -> 21.7 | F14: =IF($B14="","",MONTH($B14)) -> 2
B15: 46090 | C15: Nguyen rental — turnovers | D15: 42 | E15: =IF($D15="","",ROUND($D15*$C$4,2)) -> 29.4 | F15: =IF($B15="","",MONTH($B15)) -> 3
B16: 46101 | C16: Ferris & Co. — deep clean | D16: 26 | E16: =IF($D16="","",ROUND($D16*$C$4,2)) -> 18.2 | F16: =IF($B16="","",MONTH($B16)) -> 3
E17: =IF($D17="","",ROUND($D17*$C$4,2)) | F17: =IF($B17="","",MONTH($B17))
E18: =IF($D18="","",ROUND($D18*$C$4,2)) | F18: =IF($B18="","",MONTH($B18))
E19: =IF($D19="","",ROUND($D19*$C$4,2)) | F19: =IF($B19="","",MONTH($B19))
E20: =IF($D20="","",ROUND($D20*$C$4,2)) | F20: =IF($B20="","",MONTH($B20))
E21: =IF($D21="","",ROUND($D21*$C$4,2)) | F21: =IF($B21="","",MONTH($B21))
E22: =IF($D22="","",ROUND($D22*$C$4,2)) | F22: =IF($B22="","",MONTH($B22))
E23: =IF($D23="","",ROUND($D23*$C$4,2)) | F23: =IF($B23="","",MONTH($B23))
E24: =IF($D24="","",ROUND($D24*$C$4,2)) | F24: =IF($B24="","",MONTH($B24))
E25: =IF($D25="","",ROUND($D25*$C$4,2)) | F25: =IF($B25="","",MONTH($B25))
E26: =IF($D26="","",ROUND($D26*$C$4,2)) | F26: =IF($B26="","",MONTH($B26))
E27: =IF($D27="","",ROUND($D27*$C$4,2)) | F27: =IF($B27="","",MONTH($B27))
E28: =IF($D28="","",ROUND($D28*$C$4,2)) | F28: =IF($B28="","",MONTH($B28))
... E208: =IF($D208="","",ROUND($D208*$C$4,2)) | F208: =IF($B208="","",MONTH($B208))
B210: Standard mileage OR actual vehicle costs — not both for the same vehicle. If you take this standard-rate deduction, don't also log fuel/repairs on the Ledger. Ask your tax pro.
